2025-08-09 23:56:48 | RepitBot | ERROR    | logger.py:228 | log_telegram_error | Telegram error: {'error_type': 'Global Error Handler', 'user_id': 1229333908, 'message': 'Callback: student_view_lesson_5', 'error': "Parent instance <Lesson at 0x20da0c29550> is not bound to a Session; lazy load operation of attribute 'homeworks' cannot proceed (Background on this error at: https://sqlalche.me/e/20/bhk3)"}
2025-08-09 23:56:50 | RepitBot | ERROR    | logger.py:228 | log_telegram_error | Telegram error: {'error_type': 'Global Error Handler', 'user_id': 1229333908, 'message': 'Callback: student_view_lesson_4', 'error': "Parent instance <Lesson at 0x20da0c22410> is not bound to a Session; lazy load operation of attribute 'homeworks' cannot proceed (Background on this error at: https://sqlalche.me/e/20/bhk3)"}
2025-08-09 23:57:13 | RepitBot | ERROR    | logger.py:228 | log_telegram_error | Telegram error: {'error_type': 'Global Error Handler', 'user_id': 1229333908, 'message': 'Callback: student_view_lesson_5', 'error': "Parent instance <Lesson at 0x20da0c46310> is not bound to a Session; lazy load operation of attribute 'homeworks' cannot proceed (Background on this error at: https://sqlalche.me/e/20/bhk3)"}
2025-08-10 00:09:11 | RepitBot | ERROR    | logger.py:228 | log_telegram_error | Telegram error: {'error_type': 'Global Error Handler', 'user_id': 7722156884, 'message': 'üí¨ –°–≤—è–∑—å —Å —Ä–µ–ø–µ—Ç–∏—Ç–æ—Ä–æ–º', 'error': "'NoneType' object has no attribute 'role'"}
2025-08-10 00:51:16 | RepitBot | ERROR    | logger.py:228 | log_telegram_error | Telegram error: {'error_type': 'Global Error Handler', 'user_id': None, 'message': None, 'error': 'httpx.RemoteProtocolError: Server disconnected without sending a response.'}
2025-08-10 00:51:17 | RepitBot | ERROR    | logger.py:228 | log_telegram_error | Telegram error: {'error_type': 'Global Error Handler', 'user_id': None, 'message': None, 'error': 'httpx.ConnectError: '}
2025-08-10 02:34:41 | RepitBot | ERROR    | logger.py:228 | log_telegram_error | Telegram error: {'error_type': 'Global Error Handler', 'user_id': None, 'message': None, 'error': 'Conflict: terminated by other getUpdates request; make sure that only one bot instance is running'}
2025-08-10 02:34:45 | RepitBot | ERROR    | logger.py:228 | log_telegram_error | Telegram error: {'error_type': 'Global Error Handler', 'user_id': None, 'message': None, 'error': 'Conflict: terminated by other getUpdates request; make sure that only one bot instance is running'}
2025-08-10 02:34:47 | RepitBot | ERROR    | logger.py:228 | log_telegram_error | Telegram error: {'error_type': 'Global Error Handler', 'user_id': None, 'message': None, 'error': 'Conflict: terminated by other getUpdates request; make sure that only one bot instance is running'}
2025-08-10 02:35:12 | RepitBot | ERROR    | logger.py:228 | log_telegram_error | Telegram error: {'error_type': 'Global Error Handler', 'user_id': None, 'message': None, 'error': 'Conflict: terminated by other getUpdates request; make sure that only one bot instance is running'}
2025-08-10 02:35:18 | RepitBot | ERROR    | logger.py:228 | log_telegram_error | Telegram error: {'error_type': 'Global Error Handler', 'user_id': None, 'message': None, 'error': 'Conflict: terminated by other getUpdates request; make sure that only one bot instance is running'}
2025-08-10 02:35:20 | RepitBot | ERROR    | logger.py:228 | log_telegram_error | Telegram error: {'error_type': 'Global Error Handler', 'user_id': None, 'message': None, 'error': 'Conflict: terminated by other getUpdates request; make sure that only one bot instance is running'}
2025-08-10 02:35:24 | RepitBot | ERROR    | logger.py:228 | log_telegram_error | Telegram error: {'error_type': 'Global Error Handler', 'user_id': None, 'message': None, 'error': 'Conflict: terminated by other getUpdates request; make sure that only one bot instance is running'}
2025-08-10 02:35:29 | RepitBot | ERROR    | logger.py:228 | log_telegram_error | Telegram error: {'error_type': 'Global Error Handler', 'user_id': None, 'message': None, 'error': 'Conflict: terminated by other getUpdates request; make sure that only one bot instance is running'}
2025-08-10 02:35:36 | RepitBot | ERROR    | logger.py:228 | log_telegram_error | Telegram error: {'error_type': 'Global Error Handler', 'user_id': None, 'message': None, 'error': 'Conflict: terminated by other getUpdates request; make sure that only one bot instance is running'}
2025-08-10 02:35:43 | RepitBot | ERROR    | logger.py:228 | log_telegram_error | Telegram error: {'error_type': 'Global Error Handler', 'user_id': None, 'message': None, 'error': 'Conflict: terminated by other getUpdates request; make sure that only one bot instance is running'}
2025-08-10 02:35:53 | RepitBot | ERROR    | logger.py:228 | log_telegram_error | Telegram error: {'error_type': 'Global Error Handler', 'user_id': None, 'message': None, 'error': 'Conflict: terminated by other getUpdates request; make sure that only one bot instance is running'}
2025-08-10 02:36:26 | RepitBot | ERROR    | logger.py:228 | log_telegram_error | Telegram error: {'error_type': 'Global Error Handler', 'user_id': None, 'message': None, 'error': 'Conflict: terminated by other getUpdates request; make sure that only one bot instance is running'}
2025-08-10 02:38:37 | RepitBot | ERROR    | logger.py:228 | log_telegram_error | Telegram error: {'error_type': 'Global Error Handler', 'user_id': None, 'message': None, 'error': 'Conflict: terminated by other getUpdates request; make sure that only one bot instance is running'}
2025-08-10 02:38:42 | RepitBot | ERROR    | logger.py:228 | log_telegram_error | Telegram error: {'error_type': 'Global Error Handler', 'user_id': None, 'message': None, 'error': 'Conflict: terminated by other getUpdates request; make sure that only one bot instance is running'}
2025-08-10 02:38:43 | RepitBot | ERROR    | logger.py:228 | log_telegram_error | Telegram error: {'error_type': 'Global Error Handler', 'user_id': None, 'message': None, 'error': 'Conflict: terminated by other getUpdates request; make sure that only one bot instance is running'}
2025-08-10 02:38:48 | RepitBot | ERROR    | logger.py:228 | log_telegram_error | Telegram error: {'error_type': 'Global Error Handler', 'user_id': None, 'message': None, 'error': 'Conflict: terminated by other getUpdates request; make sure that only one bot instance is running'}
2025-08-10 02:38:51 | RepitBot | ERROR    | logger.py:228 | log_telegram_error | Telegram error: {'error_type': 'Global Error Handler', 'user_id': None, 'message': None, 'error': 'Conflict: terminated by other getUpdates request; make sure that only one bot instance is running'}
2025-08-10 02:38:54 | RepitBot | ERROR    | logger.py:228 | log_telegram_error | Telegram error: {'error_type': 'Global Error Handler', 'user_id': None, 'message': None, 'error': 'Conflict: terminated by other getUpdates request; make sure that only one bot instance is running'}
2025-08-10 02:39:12 | RepitBot | ERROR    | logger.py:228 | log_telegram_error | Telegram error: {'error_type': 'Global Error Handler', 'user_id': None, 'message': None, 'error': 'Conflict: terminated by other getUpdates request; make sure that only one bot instance is running'}
2025-08-10 02:39:16 | RepitBot | ERROR    | logger.py:228 | log_telegram_error | Telegram error: {'error_type': 'Global Error Handler', 'user_id': None, 'message': None, 'error': 'Conflict: terminated by other getUpdates request; make sure that only one bot instance is running'}
2025-08-10 02:39:20 | RepitBot | ERROR    | logger.py:228 | log_telegram_error | Telegram error: {'error_type': 'Global Error Handler', 'user_id': None, 'message': None, 'error': 'Conflict: terminated by other getUpdates request; make sure that only one bot instance is running'}
2025-08-10 02:39:28 | RepitBot | ERROR    | logger.py:228 | log_telegram_error | Telegram error: {'error_type': 'Global Error Handler', 'user_id': None, 'message': None, 'error': 'httpx.ConnectError: '}
2025-08-10 02:45:45 | RepitBot | ERROR    | logger.py:228 | log_telegram_error | Telegram error: {'error_type': 'Global Error Handler', 'user_id': None, 'message': None, 'error': 'Conflict: terminated by other getUpdates request; make sure that only one bot instance is running'}
2025-08-10 02:45:50 | RepitBot | ERROR    | logger.py:228 | log_telegram_error | Telegram error: {'error_type': 'Global Error Handler', 'user_id': None, 'message': None, 'error': 'Conflict: terminated by other getUpdates request; make sure that only one bot instance is running'}
2025-08-10 02:45:52 | RepitBot | ERROR    | logger.py:228 | log_telegram_error | Telegram error: {'error_type': 'Global Error Handler', 'user_id': None, 'message': None, 'error': 'Conflict: terminated by other getUpdates request; make sure that only one bot instance is running'}
2025-08-10 02:45:56 | RepitBot | ERROR    | logger.py:228 | log_telegram_error | Telegram error: {'error_type': 'Global Error Handler', 'user_id': None, 'message': None, 'error': 'Conflict: terminated by other getUpdates request; make sure that only one bot instance is running'}
2025-08-10 02:45:58 | RepitBot | ERROR    | logger.py:228 | log_telegram_error | Telegram error: {'error_type': 'Global Error Handler', 'user_id': None, 'message': None, 'error': 'Conflict: terminated by other getUpdates request; make sure that only one bot instance is running'}
2025-08-10 02:46:03 | RepitBot | ERROR    | logger.py:228 | log_telegram_error | Telegram error: {'error_type': 'Global Error Handler', 'user_id': None, 'message': None, 'error': 'Conflict: terminated by other getUpdates request; make sure that only one bot instance is running'}
2025-08-10 02:46:06 | RepitBot | ERROR    | logger.py:228 | log_telegram_error | Telegram error: {'error_type': 'Global Error Handler', 'user_id': None, 'message': None, 'error': 'Conflict: terminated by other getUpdates request; make sure that only one bot instance is running'}
2025-08-10 02:46:11 | RepitBot | ERROR    | logger.py:228 | log_telegram_error | Telegram error: {'error_type': 'Global Error Handler', 'user_id': None, 'message': None, 'error': 'Conflict: terminated by other getUpdates request; make sure that only one bot instance is running'}
2025-08-10 02:46:13 | RepitBot | ERROR    | logger.py:228 | log_telegram_error | Telegram error: {'error_type': 'Global Error Handler', 'user_id': None, 'message': None, 'error': 'Conflict: terminated by other getUpdates request; make sure that only one bot instance is running'}
2025-08-10 02:46:17 | RepitBot | ERROR    | logger.py:228 | log_telegram_error | Telegram error: {'error_type': 'Global Error Handler', 'user_id': None, 'message': None, 'error': 'Conflict: terminated by other getUpdates request; make sure that only one bot instance is running'}
2025-08-10 02:46:19 | RepitBot | ERROR    | logger.py:228 | log_telegram_error | Telegram error: {'error_type': 'Global Error Handler', 'user_id': None, 'message': None, 'error': 'Conflict: terminated by other getUpdates request; make sure that only one bot instance is running'}
2025-08-10 02:46:25 | RepitBot | ERROR    | logger.py:228 | log_telegram_error | Telegram error: {'error_type': 'Global Error Handler', 'user_id': None, 'message': None, 'error': 'Conflict: terminated by other getUpdates request; make sure that only one bot instance is running'}
2025-08-10 02:46:28 | RepitBot | ERROR    | logger.py:228 | log_telegram_error | Telegram error: {'error_type': 'Global Error Handler', 'user_id': None, 'message': None, 'error': 'Conflict: terminated by other getUpdates request; make sure that only one bot instance is running'}
2025-08-10 02:46:34 | RepitBot | ERROR    | logger.py:228 | log_telegram_error | Telegram error: {'error_type': 'Global Error Handler', 'user_id': None, 'message': None, 'error': 'Conflict: terminated by other getUpdates request; make sure that only one bot instance is running'}
2025-08-10 02:46:38 | RepitBot | ERROR    | logger.py:228 | log_telegram_error | Telegram error: {'error_type': 'Global Error Handler', 'user_id': None, 'message': None, 'error': 'Conflict: terminated by other getUpdates request; make sure that only one bot instance is running'}
2025-08-10 02:46:42 | RepitBot | ERROR    | logger.py:228 | log_telegram_error | Telegram error: {'error_type': 'Global Error Handler', 'user_id': None, 'message': None, 'error': 'Conflict: terminated by other getUpdates request; make sure that only one bot instance is running'}
2025-08-10 02:46:51 | RepitBot | ERROR    | logger.py:228 | log_telegram_error | Telegram error: {'error_type': 'Global Error Handler', 'user_id': None, 'message': None, 'error': 'httpx.ConnectError: '}
2025-08-10 02:48:38 | RepitBot | ERROR    | logger.py:228 | log_telegram_error | Telegram error: {'error_type': 'Global Error Handler', 'user_id': None, 'message': None, 'error': 'Conflict: terminated by other getUpdates request; make sure that only one bot instance is running'}
2025-08-10 02:48:43 | RepitBot | ERROR    | logger.py:228 | log_telegram_error | Telegram error: {'error_type': 'Global Error Handler', 'user_id': None, 'message': None, 'error': 'Conflict: terminated by other getUpdates request; make sure that only one bot instance is running'}
2025-08-10 02:48:45 | RepitBot | ERROR    | logger.py:228 | log_telegram_error | Telegram error: {'error_type': 'Global Error Handler', 'user_id': None, 'message': None, 'error': 'Conflict: terminated by other getUpdates request; make sure that only one bot instance is running'}
2025-08-10 02:48:50 | RepitBot | ERROR    | logger.py:228 | log_telegram_error | Telegram error: {'error_type': 'Global Error Handler', 'user_id': None, 'message': None, 'error': 'Conflict: terminated by other getUpdates request; make sure that only one bot instance is running'}
2025-08-10 02:48:52 | RepitBot | ERROR    | logger.py:228 | log_telegram_error | Telegram error: {'error_type': 'Global Error Handler', 'user_id': None, 'message': None, 'error': 'Conflict: terminated by other getUpdates request; make sure that only one bot instance is running'}
2025-08-10 02:48:55 | RepitBot | ERROR    | logger.py:228 | log_telegram_error | Telegram error: {'error_type': 'Global Error Handler', 'user_id': None, 'message': None, 'error': 'Conflict: terminated by other getUpdates request; make sure that only one bot instance is running'}
2025-08-10 02:49:01 | RepitBot | ERROR    | logger.py:228 | log_telegram_error | Telegram error: {'error_type': 'Global Error Handler', 'user_id': None, 'message': None, 'error': 'Conflict: terminated by other getUpdates request; make sure that only one bot instance is running'}
2025-08-10 02:49:05 | RepitBot | ERROR    | logger.py:228 | log_telegram_error | Telegram error: {'error_type': 'Global Error Handler', 'user_id': None, 'message': None, 'error': 'Conflict: terminated by other getUpdates request; make sure that only one bot instance is running'}
2025-08-10 02:49:09 | RepitBot | ERROR    | logger.py:228 | log_telegram_error | Telegram error: {'error_type': 'Global Error Handler', 'user_id': None, 'message': None, 'error': 'Conflict: terminated by other getUpdates request; make sure that only one bot instance is running'}
2025-08-10 02:49:17 | RepitBot | ERROR    | logger.py:228 | log_telegram_error | Telegram error: {'error_type': 'Global Error Handler', 'user_id': None, 'message': None, 'error': 'httpx.ConnectError: '}
2025-08-10 02:50:28 | RepitBot | ERROR    | logger.py:228 | log_telegram_error | Telegram error: {'error_type': 'Global Error Handler', 'user_id': None, 'message': None, 'error': 'Conflict: terminated by other getUpdates request; make sure that only one bot instance is running'}
2025-08-10 02:50:34 | RepitBot | ERROR    | logger.py:228 | log_telegram_error | Telegram error: {'error_type': 'Global Error Handler', 'user_id': None, 'message': None, 'error': 'Conflict: terminated by other getUpdates request; make sure that only one bot instance is running'}
2025-08-10 02:50:36 | RepitBot | ERROR    | logger.py:228 | log_telegram_error | Telegram error: {'error_type': 'Global Error Handler', 'user_id': None, 'message': None, 'error': 'Conflict: terminated by other getUpdates request; make sure that only one bot instance is running'}
2025-08-10 02:50:40 | RepitBot | ERROR    | logger.py:228 | log_telegram_error | Telegram error: {'error_type': 'Global Error Handler', 'user_id': None, 'message': None, 'error': 'Conflict: terminated by other getUpdates request; make sure that only one bot instance is running'}
2025-08-10 02:50:43 | RepitBot | ERROR    | logger.py:228 | log_telegram_error | Telegram error: {'error_type': 'Global Error Handler', 'user_id': None, 'message': None, 'error': 'Conflict: terminated by other getUpdates request; make sure that only one bot instance is running'}
2025-08-10 02:50:48 | RepitBot | ERROR    | logger.py:228 | log_telegram_error | Telegram error: {'error_type': 'Global Error Handler', 'user_id': None, 'message': None, 'error': 'Conflict: terminated by other getUpdates request; make sure that only one bot instance is running'}
2025-08-10 02:50:51 | RepitBot | ERROR    | logger.py:228 | log_telegram_error | Telegram error: {'error_type': 'Global Error Handler', 'user_id': None, 'message': None, 'error': 'Conflict: terminated by other getUpdates request; make sure that only one bot instance is running'}
2025-08-10 02:50:57 | RepitBot | ERROR    | logger.py:228 | log_telegram_error | Telegram error: {'error_type': 'Global Error Handler', 'user_id': None, 'message': None, 'error': 'Conflict: terminated by other getUpdates request; make sure that only one bot instance is running'}
2025-08-10 02:51:01 | RepitBot | ERROR    | logger.py:228 | log_telegram_error | Telegram error: {'error_type': 'Global Error Handler', 'user_id': None, 'message': None, 'error': 'Conflict: terminated by other getUpdates request; make sure that only one bot instance is running'}
2025-08-10 02:51:05 | RepitBot | ERROR    | logger.py:228 | log_telegram_error | Telegram error: {'error_type': 'Global Error Handler', 'user_id': None, 'message': None, 'error': 'Conflict: terminated by other getUpdates request; make sure that only one bot instance is running'}
2025-08-10 02:51:12 | RepitBot | ERROR    | logger.py:228 | log_telegram_error | Telegram error: {'error_type': 'Global Error Handler', 'user_id': None, 'message': None, 'error': 'Conflict: terminated by other getUpdates request; make sure that only one bot instance is running'}
2025-08-10 02:51:19 | RepitBot | ERROR    | logger.py:228 | log_telegram_error | Telegram error: {'error_type': 'Global Error Handler', 'user_id': None, 'message': None, 'error': 'Conflict: terminated by other getUpdates request; make sure that only one bot instance is running'}
2025-08-10 02:51:29 | RepitBot | ERROR    | logger.py:228 | log_telegram_error | Telegram error: {'error_type': 'Global Error Handler', 'user_id': None, 'message': None, 'error': 'Conflict: terminated by other getUpdates request; make sure that only one bot instance is running'}
2025-08-10 02:51:39 | RepitBot | ERROR    | logger.py:228 | log_telegram_error | Telegram error: {'error_type': 'Global Error Handler', 'user_id': None, 'message': None, 'error': 'Conflict: terminated by other getUpdates request; make sure that only one bot instance is running'}
2025-08-10 02:51:53 | RepitBot | ERROR    | logger.py:228 | log_telegram_error | Telegram error: {'error_type': 'Global Error Handler', 'user_id': None, 'message': None, 'error': 'Conflict: terminated by other getUpdates request; make sure that only one bot instance is running'}
2025-08-10 02:52:07 | RepitBot | ERROR    | logger.py:228 | log_telegram_error | Telegram error: {'error_type': 'Global Error Handler', 'user_id': None, 'message': None, 'error': 'Conflict: terminated by other getUpdates request; make sure that only one bot instance is running'}
2025-08-10 02:52:27 | RepitBot | ERROR    | logger.py:228 | log_telegram_error | Telegram error: {'error_type': 'Global Error Handler', 'user_id': None, 'message': None, 'error': 'Conflict: terminated by other getUpdates request; make sure that only one bot instance is running'}
2025-08-10 02:52:46 | RepitBot | ERROR    | logger.py:228 | log_telegram_error | Telegram error: {'error_type': 'Global Error Handler', 'user_id': None, 'message': None, 'error': 'Conflict: terminated by other getUpdates request; make sure that only one bot instance is running'}
2025-08-10 02:53:40 | RepitBot | ERROR    | logger.py:228 | log_telegram_error | Telegram error: {'error_type': 'Global Error Handler', 'user_id': None, 'message': None, 'error': 'Conflict: terminated by other getUpdates request; make sure that only one bot instance is running'}
2025-08-10 02:54:17 | RepitBot | ERROR    | logger.py:228 | log_telegram_error | Telegram error: {'error_type': 'Global Error Handler', 'user_id': None, 'message': None, 'error': 'Conflict: terminated by other getUpdates request; make sure that only one bot instance is running'}
2025-08-10 02:54:22 | RepitBot | ERROR    | logger.py:228 | log_telegram_error | Telegram error: {'error_type': 'Global Error Handler', 'user_id': None, 'message': None, 'error': 'Conflict: terminated by other getUpdates request; make sure that only one bot instance is running'}
2025-08-10 02:54:24 | RepitBot | ERROR    | logger.py:228 | log_telegram_error | Telegram error: {'error_type': 'Global Error Handler', 'user_id': None, 'message': None, 'error': 'Conflict: terminated by other getUpdates request; make sure that only one bot instance is running'}
2025-08-10 02:54:29 | RepitBot | ERROR    | logger.py:228 | log_telegram_error | Telegram error: {'error_type': 'Global Error Handler', 'user_id': None, 'message': None, 'error': 'Conflict: terminated by other getUpdates request; make sure that only one bot instance is running'}
2025-08-10 02:54:31 | RepitBot | ERROR    | logger.py:228 | log_telegram_error | Telegram error: {'error_type': 'Global Error Handler', 'user_id': None, 'message': None, 'error': 'Conflict: terminated by other getUpdates request; make sure that only one bot instance is running'}
2025-08-10 02:54:37 | RepitBot | ERROR    | logger.py:228 | log_telegram_error | Telegram error: {'error_type': 'Global Error Handler', 'user_id': None, 'message': None, 'error': 'Conflict: terminated by other getUpdates request; make sure that only one bot instance is running'}
2025-08-10 02:54:40 | RepitBot | ERROR    | logger.py:228 | log_telegram_error | Telegram error: {'error_type': 'Global Error Handler', 'user_id': None, 'message': None, 'error': 'Conflict: terminated by other getUpdates request; make sure that only one bot instance is running'}
2025-08-10 02:54:44 | RepitBot | ERROR    | logger.py:228 | log_telegram_error | Telegram error: {'error_type': 'Global Error Handler', 'user_id': None, 'message': None, 'error': 'Conflict: terminated by other getUpdates request; make sure that only one bot instance is running'}
2025-08-10 02:54:48 | RepitBot | ERROR    | logger.py:228 | log_telegram_error | Telegram error: {'error_type': 'Global Error Handler', 'user_id': None, 'message': None, 'error': 'Conflict: terminated by other getUpdates request; make sure that only one bot instance is running'}
2025-08-10 02:54:54 | RepitBot | ERROR    | logger.py:228 | log_telegram_error | Telegram error: {'error_type': 'Global Error Handler', 'user_id': None, 'message': None, 'error': 'Conflict: terminated by other getUpdates request; make sure that only one bot instance is running'}
2025-08-10 02:54:55 | RepitBot | ERROR    | logger.py:228 | log_telegram_error | Telegram error: {'error_type': 'Global Error Handler', 'user_id': None, 'message': None, 'error': 'Conflict: terminated by other getUpdates request; make sure that only one bot instance is running'}
2025-08-10 02:55:00 | RepitBot | ERROR    | logger.py:228 | log_telegram_error | Telegram error: {'error_type': 'Global Error Handler', 'user_id': None, 'message': None, 'error': 'Conflict: terminated by other getUpdates request; make sure that only one bot instance is running'}
2025-08-10 02:55:12 | RepitBot | ERROR    | logger.py:228 | log_telegram_error | Telegram error: {'error_type': 'Global Error Handler', 'user_id': None, 'message': None, 'error': 'httpx.ConnectError: '}
2025-08-10 03:03:56 | RepitBot | ERROR    | logger.py:228 | log_telegram_error | Telegram error: {'error_type': 'Global Error Handler', 'user_id': None, 'message': None, 'error': 'Conflict: terminated by other getUpdates request; make sure that only one bot instance is running'}
2025-08-10 03:04:01 | RepitBot | ERROR    | logger.py:228 | log_telegram_error | Telegram error: {'error_type': 'Global Error Handler', 'user_id': None, 'message': None, 'error': 'Conflict: terminated by other getUpdates request; make sure that only one bot instance is running'}
2025-08-10 03:04:02 | RepitBot | ERROR    | logger.py:228 | log_telegram_error | Telegram error: {'error_type': 'Global Error Handler', 'user_id': None, 'message': None, 'error': 'Conflict: terminated by other getUpdates request; make sure that only one bot instance is running'}
2025-08-10 03:04:08 | RepitBot | ERROR    | logger.py:228 | log_telegram_error | Telegram error: {'error_type': 'Global Error Handler', 'user_id': None, 'message': None, 'error': 'Conflict: terminated by other getUpdates request; make sure that only one bot instance is running'}
2025-08-10 03:04:10 | RepitBot | ERROR    | logger.py:228 | log_telegram_error | Telegram error: {'error_type': 'Global Error Handler', 'user_id': None, 'message': None, 'error': 'Conflict: terminated by other getUpdates request; make sure that only one bot instance is running'}
2025-08-10 03:04:16 | RepitBot | ERROR    | logger.py:228 | log_telegram_error | Telegram error: {'error_type': 'Global Error Handler', 'user_id': None, 'message': None, 'error': 'Conflict: terminated by other getUpdates request; make sure that only one bot instance is running'}
2025-08-10 03:04:19 | RepitBot | ERROR    | logger.py:228 | log_telegram_error | Telegram error: {'error_type': 'Global Error Handler', 'user_id': None, 'message': None, 'error': 'Conflict: terminated by other getUpdates request; make sure that only one bot instance is running'}
2025-08-10 03:04:23 | RepitBot | ERROR    | logger.py:228 | log_telegram_error | Telegram error: {'error_type': 'Global Error Handler', 'user_id': None, 'message': None, 'error': 'Conflict: terminated by other getUpdates request; make sure that only one bot instance is running'}
2025-08-10 03:04:27 | RepitBot | ERROR    | logger.py:228 | log_telegram_error | Telegram error: {'error_type': 'Global Error Handler', 'user_id': None, 'message': None, 'error': 'Conflict: terminated by other getUpdates request; make sure that only one bot instance is running'}
2025-08-10 03:04:35 | RepitBot | ERROR    | logger.py:228 | log_telegram_error | Telegram error: {'error_type': 'Global Error Handler', 'user_id': None, 'message': None, 'error': 'Conflict: terminated by other getUpdates request; make sure that only one bot instance is running'}
2025-08-10 03:04:43 | RepitBot | ERROR    | logger.py:228 | log_telegram_error | Telegram error: {'error_type': 'Global Error Handler', 'user_id': None, 'message': None, 'error': 'Conflict: terminated by other getUpdates request; make sure that only one bot instance is running'}
2025-08-10 03:04:53 | RepitBot | ERROR    | logger.py:228 | log_telegram_error | Telegram error: {'error_type': 'Global Error Handler', 'user_id': None, 'message': None, 'error': 'Conflict: terminated by other getUpdates request; make sure that only one bot instance is running'}
2025-08-10 03:05:03 | RepitBot | ERROR    | logger.py:228 | log_telegram_error | Telegram error: {'error_type': 'Global Error Handler', 'user_id': None, 'message': None, 'error': 'Conflict: terminated by other getUpdates request; make sure that only one bot instance is running'}
2025-08-10 03:05:16 | RepitBot | ERROR    | logger.py:228 | log_telegram_error | Telegram error: {'error_type': 'Global Error Handler', 'user_id': None, 'message': None, 'error': 'Conflict: terminated by other getUpdates request; make sure that only one bot instance is running'}
2025-08-10 03:05:30 | RepitBot | ERROR    | logger.py:228 | log_telegram_error | Telegram error: {'error_type': 'Global Error Handler', 'user_id': None, 'message': None, 'error': 'Conflict: terminated by other getUpdates request; make sure that only one bot instance is running'}
2025-08-10 03:05:51 | RepitBot | ERROR    | logger.py:228 | log_telegram_error | Telegram error: {'error_type': 'Global Error Handler', 'user_id': None, 'message': None, 'error': 'Conflict: terminated by other getUpdates request; make sure that only one bot instance is running'}
2025-08-10 03:06:11 | RepitBot | ERROR    | logger.py:228 | log_telegram_error | Telegram error: {'error_type': 'Global Error Handler', 'user_id': None, 'message': None, 'error': 'Conflict: terminated by other getUpdates request; make sure that only one bot instance is running'}
2025-08-10 03:06:39 | RepitBot | ERROR    | logger.py:228 | log_telegram_error | Telegram error: {'error_type': 'Global Error Handler', 'user_id': None, 'message': None, 'error': 'Conflict: terminated by other getUpdates request; make sure that only one bot instance is running'}
2025-08-10 03:07:08 | RepitBot | ERROR    | logger.py:228 | log_telegram_error | Telegram error: {'error_type': 'Global Error Handler', 'user_id': None, 'message': None, 'error': 'Conflict: terminated by other getUpdates request; make sure that only one bot instance is running'}
2025-08-10 03:07:40 | RepitBot | ERROR    | logger.py:228 | log_telegram_error | Telegram error: {'error_type': 'Global Error Handler', 'user_id': None, 'message': None, 'error': 'Conflict: terminated by other getUpdates request; make sure that only one bot instance is running'}
2025-08-10 03:07:45 | RepitBot | ERROR    | logger.py:228 | log_telegram_error | Telegram error: {'error_type': 'Global Error Handler', 'user_id': None, 'message': None, 'error': 'Conflict: terminated by other getUpdates request; make sure that only one bot instance is running'}
2025-08-10 03:08:18 | RepitBot | ERROR    | logger.py:228 | log_telegram_error | Telegram error: {'error_type': 'Global Error Handler', 'user_id': None, 'message': None, 'error': 'Conflict: terminated by other getUpdates request; make sure that only one bot instance is running'}
2025-08-10 03:08:22 | RepitBot | ERROR    | logger.py:228 | log_telegram_error | Telegram error: {'error_type': 'Global Error Handler', 'user_id': None, 'message': None, 'error': 'Conflict: terminated by other getUpdates request; make sure that only one bot instance is running'}
2025-08-10 03:18:19 | RepitBot | ERROR    | logger.py:228 | log_telegram_error | Telegram error: {'error_type': 'Global Error Handler', 'user_id': None, 'message': None, 'error': 'httpx.ConnectError: '}
2025-08-10 17:43:36 | RepitBot | ERROR    | logger.py:228 | log_telegram_error | Telegram error: {'error_type': 'Global Error Handler', 'user_id': None, 'message': None, 'error': 'httpx.ConnectError: '}
2025-08-10 18:02:27 | RepitBot | ERROR    | logger.py:228 | log_telegram_error | Telegram error: {'error_type': 'Global Error Handler', 'user_id': 1229333908, 'message': 'Callback: tutor_view_student_6', 'error': "cannot import name 'show_student_profile' from 'src.handlers' (C:\\Users\\F12$\\Desktop\\repitbot\\src\\handlers\\__init__.py)"}
2025-08-10 18:02:28 | RepitBot | ERROR    | logger.py:228 | log_telegram_error | Telegram error: {'error_type': 'Global Error Handler', 'user_id': 1229333908, 'message': 'Callback: tutor_view_student_7', 'error': "cannot import name 'show_student_profile' from 'src.handlers' (C:\\Users\\F12$\\Desktop\\repitbot\\src\\handlers\\__init__.py)"}
2025-08-10 18:02:30 | RepitBot | ERROR    | logger.py:228 | log_telegram_error | Telegram error: {'error_type': 'Global Error Handler', 'user_id': 1229333908, 'message': 'Callback: tutor_view_student_9', 'error': "cannot import name 'show_student_profile' from 'src.handlers' (C:\\Users\\F12$\\Desktop\\repitbot\\src\\handlers\\__init__.py)"}
2025-08-10 18:02:32 | RepitBot | ERROR    | logger.py:228 | log_telegram_error | Telegram error: {'error_type': 'Global Error Handler', 'user_id': 1229333908, 'message': 'Callback: report_select_student_6', 'error': "cannot import name 'show_student_profile' from 'src.handlers' (C:\\Users\\F12$\\Desktop\\repitbot\\src\\handlers\\__init__.py)"}
2025-08-10 18:02:36 | RepitBot | ERROR    | logger.py:228 | log_telegram_error | Telegram error: {'error_type': 'Global Error Handler', 'user_id': 1229333908, 'message': 'Callback: tutor_view_material_1', 'error': "cannot import name 'show_student_profile' from 'src.handlers' (C:\\Users\\F12$\\Desktop\\repitbot\\src\\handlers\\__init__.py)"}
2025-08-10 18:19:06 | RepitBot | ERROR    | logger.py:228 | log_telegram_error | Telegram error: {'error_type': 'Global Error Handler', 'user_id': None, 'message': None, 'error': 'httpx.RemoteProtocolError: Server disconnected without sending a response.'}
2025-08-10 18:36:01 | RepitBot | ERROR    | logger.py:228 | log_telegram_error | Telegram error: {'error_type': 'Global Error Handler', 'user_id': None, 'message': None, 'error': 'httpx.RemoteProtocolError: Server disconnected without sending a response.'}
2025-08-10 18:36:04 | RepitBot | ERROR    | logger.py:228 | log_telegram_error | Telegram error: {'error_type': 'Global Error Handler', 'user_id': None, 'message': None, 'error': 'httpx.ConnectError: '}
2025-08-10 18:45:15 | RepitBot | ERROR    | logger.py:228 | log_telegram_error | Telegram error: {'error_type': 'Global Error Handler', 'user_id': None, 'message': None, 'error': 'httpx.RemoteProtocolError: Server disconnected without sending a response.'}
2025-08-10 18:45:18 | RepitBot | ERROR    | logger.py:228 | log_telegram_error | Telegram error: {'error_type': 'Global Error Handler', 'user_id': None, 'message': None, 'error': 'httpx.ConnectError: '}
2025-08-10 18:47:14 | RepitBot.HealthMonitor | ERROR    | health_monitor.py:83 | run_check | Health check bot_connection timeout after 10s
2025-08-10 18:47:14 | RepitBot.HealthMonitor | CRITICAL | health_monitor.py:139 | _handle_critical_failure | üö® CRITICAL: Health check bot_connection failed 2 times
2025-08-10 18:49:08 | RepitBot.HealthMonitor | CRITICAL | health_monitor.py:139 | _handle_critical_failure | üö® CRITICAL: Health check bot_connection failed 3 times
2025-08-10 18:49:15 | RepitBot.HealthMonitor | ERROR    | health_monitor.py:174 | _recover_bot_connection | ‚ùå Failed to recover bot connection: httpx.ConnectError: 
2025-08-10 18:52:01 | RepitBot.HealthMonitor | ERROR    | health_monitor.py:83 | run_check | Health check bot_connection timeout after 10s
2025-08-10 18:52:01 | RepitBot.HealthMonitor | CRITICAL | health_monitor.py:139 | _handle_critical_failure | üö® CRITICAL: Health check bot_connection failed 1 times
2025-08-10 18:55:54 | RepitBot.HealthMonitor | CRITICAL | health_monitor.py:139 | _handle_critical_failure | üö® CRITICAL: Health check bot_connection failed 3 times
2025-08-10 18:55:54 | RepitBot.HealthMonitor | ERROR    | health_monitor.py:174 | _recover_bot_connection | ‚ùå Failed to recover bot connection: httpx.ConnectError: 
2025-08-10 18:57:08 | RepitBot.HealthMonitor | CRITICAL | health_monitor.py:139 | _handle_critical_failure | üö® CRITICAL: Health check bot_connection failed 3 times
2025-08-10 18:57:10 | RepitBot.HealthMonitor | ERROR    | health_monitor.py:174 | _recover_bot_connection | ‚ùå Failed to recover bot connection: httpx.ConnectError: All connection attempts failed
2025-08-10 18:57:56 | RepitBot.HealthMonitor | CRITICAL | health_monitor.py:139 | _handle_critical_failure | üö® CRITICAL: Health check bot_connection failed 4 times
2025-08-10 18:57:58 | RepitBot.HealthMonitor | ERROR    | health_monitor.py:174 | _recover_bot_connection | ‚ùå Failed to recover bot connection: httpx.ConnectError: All connection attempts failed
2025-08-10 19:25:34 | RepitBot.HealthMonitor | CRITICAL | health_monitor.py:139 | _handle_critical_failure | üö® CRITICAL: Health check bot_connection failed 3 times
2025-08-10 19:25:39 | RepitBot.HealthMonitor | ERROR    | health_monitor.py:174 | _recover_bot_connection | ‚ùå Failed to recover bot connection: httpx.ConnectError: 
2025-08-10 19:26:21 | RepitBot.HealthMonitor | CRITICAL | health_monitor.py:139 | _handle_critical_failure | üö® CRITICAL: Health check bot_connection failed 3 times
2025-08-10 19:26:26 | RepitBot.HealthMonitor | ERROR    | health_monitor.py:174 | _recover_bot_connection | ‚ùå Failed to recover bot connection: httpx.ConnectError: 
2025-08-10 20:22:51 | RepitBot.HealthMonitor | ERROR    | health_monitor.py:83 | run_check | Health check bot_connection timeout after 10s
2025-08-10 20:22:51 | RepitBot.HealthMonitor | CRITICAL | health_monitor.py:139 | _handle_critical_failure | üö® CRITICAL: Health check bot_connection failed 4 times
2025-08-10 20:22:52 | RepitBot.HealthMonitor | ERROR    | health_monitor.py:174 | _recover_bot_connection | ‚ùå Failed to recover bot connection: httpx.ConnectError: 
2025-08-11 16:17:28 | RepitBot.HealthMonitor | CRITICAL | health_monitor.py:139 | _handle_critical_failure | üö® CRITICAL: Health check bot_connection failed 5 times
2025-08-11 16:17:28 | RepitBot.HealthMonitor | CRITICAL | health_monitor.py:139 | _handle_critical_failure | üö® CRITICAL: Health check bot_connection failed 3 times
2025-08-11 16:17:28 | RepitBot.HealthMonitor | ERROR    | health_monitor.py:174 | _recover_bot_connection | ‚ùå Failed to recover bot connection: httpx.ConnectError: 
2025-08-11 16:17:28 | RepitBot.HealthMonitor | ERROR    | health_monitor.py:174 | _recover_bot_connection | ‚ùå Failed to recover bot connection: httpx.ConnectError: 
2025-08-11 16:19:33 | RepitBot.HealthMonitor | CRITICAL | health_monitor.py:139 | _handle_critical_failure | üö® CRITICAL: Health check bot_connection failed 4 times
2025-08-11 16:19:33 | RepitBot.HealthMonitor | CRITICAL | health_monitor.py:139 | _handle_critical_failure | üö® CRITICAL: Health check bot_connection failed 6 times
2025-08-11 16:19:38 | RepitBot.HealthMonitor | ERROR    | health_monitor.py:174 | _recover_bot_connection | ‚ùå Failed to recover bot connection: httpx.ConnectError: 
2025-08-11 16:19:38 | RepitBot.HealthMonitor | ERROR    | health_monitor.py:174 | _recover_bot_connection | ‚ùå Failed to recover bot connection: httpx.ConnectError: 
2025-08-11 16:21:33 | RepitBot.HealthMonitor | CRITICAL | health_monitor.py:139 | _handle_critical_failure | üö® CRITICAL: Health check bot_connection failed 7 times
2025-08-11 16:21:33 | RepitBot.HealthMonitor | CRITICAL | health_monitor.py:139 | _handle_critical_failure | üö® CRITICAL: Health check bot_connection failed 5 times
2025-08-11 16:21:38 | RepitBot.HealthMonitor | ERROR    | health_monitor.py:174 | _recover_bot_connection | ‚ùå Failed to recover bot connection: httpx.ConnectError: 
2025-08-11 16:21:38 | RepitBot.HealthMonitor | ERROR    | health_monitor.py:174 | _recover_bot_connection | ‚ùå Failed to recover bot connection: httpx.ConnectError: 
2025-08-11 16:23:33 | RepitBot.HealthMonitor | CRITICAL | health_monitor.py:139 | _handle_critical_failure | üö® CRITICAL: Health check bot_connection failed 6 times
2025-08-11 16:23:33 | RepitBot.HealthMonitor | CRITICAL | health_monitor.py:139 | _handle_critical_failure | üö® CRITICAL: Health check bot_connection failed 8 times
2025-08-11 16:23:38 | RepitBot.HealthMonitor | ERROR    | health_monitor.py:174 | _recover_bot_connection | ‚ùå Failed to recover bot connection: httpx.ConnectError: 
2025-08-11 16:23:38 | RepitBot.HealthMonitor | ERROR    | health_monitor.py:174 | _recover_bot_connection | ‚ùå Failed to recover bot connection: httpx.ConnectError: 
2025-08-11 16:25:33 | RepitBot.HealthMonitor | CRITICAL | health_monitor.py:139 | _handle_critical_failure | üö® CRITICAL: Health check bot_connection failed 7 times
2025-08-11 16:25:34 | RepitBot.HealthMonitor | CRITICAL | health_monitor.py:139 | _handle_critical_failure | üö® CRITICAL: Health check bot_connection failed 9 times
2025-08-11 16:25:39 | RepitBot.HealthMonitor | ERROR    | health_monitor.py:174 | _recover_bot_connection | ‚ùå Failed to recover bot connection: httpx.ConnectError: 
2025-08-11 16:25:39 | RepitBot.HealthMonitor | ERROR    | health_monitor.py:174 | _recover_bot_connection | ‚ùå Failed to recover bot connection: httpx.ConnectError: 
2025-08-11 16:27:34 | RepitBot.HealthMonitor | CRITICAL | health_monitor.py:139 | _handle_critical_failure | üö® CRITICAL: Health check bot_connection failed 10 times
2025-08-11 16:27:34 | RepitBot.HealthMonitor | CRITICAL | health_monitor.py:139 | _handle_critical_failure | üö® CRITICAL: Health check bot_connection failed 8 times
2025-08-11 16:27:39 | RepitBot.HealthMonitor | ERROR    | health_monitor.py:174 | _recover_bot_connection | ‚ùå Failed to recover bot connection: httpx.ConnectError: 
2025-08-11 16:27:39 | RepitBot.HealthMonitor | ERROR    | health_monitor.py:174 | _recover_bot_connection | ‚ùå Failed to recover bot connection: httpx.ConnectError: 
2025-08-11 16:29:34 | RepitBot.HealthMonitor | CRITICAL | health_monitor.py:139 | _handle_critical_failure | üö® CRITICAL: Health check bot_connection failed 9 times
2025-08-11 16:29:34 | RepitBot.HealthMonitor | CRITICAL | health_monitor.py:139 | _handle_critical_failure | üö® CRITICAL: Health check bot_connection failed 11 times
2025-08-11 16:29:39 | RepitBot.HealthMonitor | ERROR    | health_monitor.py:174 | _recover_bot_connection | ‚ùå Failed to recover bot connection: httpx.ConnectError: 
2025-08-11 16:29:39 | RepitBot.HealthMonitor | ERROR    | health_monitor.py:174 | _recover_bot_connection | ‚ùå Failed to recover bot connection: httpx.ConnectError: 
2025-08-11 16:31:34 | RepitBot.HealthMonitor | CRITICAL | health_monitor.py:139 | _handle_critical_failure | üö® CRITICAL: Health check bot_connection failed 12 times
2025-08-11 16:31:34 | RepitBot.HealthMonitor | CRITICAL | health_monitor.py:139 | _handle_critical_failure | üö® CRITICAL: Health check bot_connection failed 10 times
2025-08-11 16:31:39 | RepitBot.HealthMonitor | ERROR    | health_monitor.py:174 | _recover_bot_connection | ‚ùå Failed to recover bot connection: httpx.ConnectError: 
2025-08-11 16:31:39 | RepitBot.HealthMonitor | ERROR    | health_monitor.py:174 | _recover_bot_connection | ‚ùå Failed to recover bot connection: httpx.ConnectError: 
2025-08-11 16:33:34 | RepitBot.HealthMonitor | CRITICAL | health_monitor.py:139 | _handle_critical_failure | üö® CRITICAL: Health check bot_connection failed 13 times
2025-08-11 16:33:34 | RepitBot.HealthMonitor | CRITICAL | health_monitor.py:139 | _handle_critical_failure | üö® CRITICAL: Health check bot_connection failed 11 times
2025-08-11 16:33:39 | RepitBot.HealthMonitor | ERROR    | health_monitor.py:174 | _recover_bot_connection | ‚ùå Failed to recover bot connection: httpx.ConnectError: 
2025-08-11 16:33:39 | RepitBot.HealthMonitor | ERROR    | health_monitor.py:174 | _recover_bot_connection | ‚ùå Failed to recover bot connection: httpx.ConnectError: 
2025-08-11 16:35:34 | RepitBot.HealthMonitor | CRITICAL | health_monitor.py:139 | _handle_critical_failure | üö® CRITICAL: Health check bot_connection failed 14 times
2025-08-11 16:35:34 | RepitBot.HealthMonitor | CRITICAL | health_monitor.py:139 | _handle_critical_failure | üö® CRITICAL: Health check bot_connection failed 12 times
2025-08-11 16:35:39 | RepitBot.HealthMonitor | ERROR    | health_monitor.py:174 | _recover_bot_connection | ‚ùå Failed to recover bot connection: httpx.ConnectError: 
2025-08-11 16:35:39 | RepitBot.HealthMonitor | ERROR    | health_monitor.py:174 | _recover_bot_connection | ‚ùå Failed to recover bot connection: httpx.ConnectError: 
2025-08-11 16:37:34 | RepitBot.HealthMonitor | CRITICAL | health_monitor.py:139 | _handle_critical_failure | üö® CRITICAL: Health check bot_connection failed 13 times
2025-08-11 16:37:34 | RepitBot.HealthMonitor | CRITICAL | health_monitor.py:139 | _handle_critical_failure | üö® CRITICAL: Health check bot_connection failed 15 times
2025-08-11 16:37:39 | RepitBot.HealthMonitor | ERROR    | health_monitor.py:174 | _recover_bot_connection | ‚ùå Failed to recover bot connection: httpx.ConnectError: 
2025-08-11 16:37:39 | RepitBot.HealthMonitor | ERROR    | health_monitor.py:174 | _recover_bot_connection | ‚ùå Failed to recover bot connection: httpx.ConnectError: 
2025-08-11 16:39:35 | RepitBot.HealthMonitor | CRITICAL | health_monitor.py:139 | _handle_critical_failure | üö® CRITICAL: Health check bot_connection failed 14 times
2025-08-11 16:39:35 | RepitBot.HealthMonitor | CRITICAL | health_monitor.py:139 | _handle_critical_failure | üö® CRITICAL: Health check bot_connection failed 16 times
2025-08-11 16:39:40 | RepitBot.HealthMonitor | ERROR    | health_monitor.py:174 | _recover_bot_connection | ‚ùå Failed to recover bot connection: httpx.ConnectError: 
2025-08-11 16:39:40 | RepitBot.HealthMonitor | ERROR    | health_monitor.py:174 | _recover_bot_connection | ‚ùå Failed to recover bot connection: httpx.ConnectError: 
2025-08-11 16:41:35 | RepitBot.HealthMonitor | CRITICAL | health_monitor.py:139 | _handle_critical_failure | üö® CRITICAL: Health check bot_connection failed 15 times
2025-08-11 16:41:35 | RepitBot.HealthMonitor | CRITICAL | health_monitor.py:139 | _handle_critical_failure | üö® CRITICAL: Health check bot_connection failed 17 times
2025-08-11 16:41:40 | RepitBot.HealthMonitor | ERROR    | health_monitor.py:174 | _recover_bot_connection | ‚ùå Failed to recover bot connection: httpx.ConnectError: 
2025-08-11 16:41:40 | RepitBot.HealthMonitor | ERROR    | health_monitor.py:174 | _recover_bot_connection | ‚ùå Failed to recover bot connection: httpx.ConnectError: 
2025-08-11 16:43:35 | RepitBot.HealthMonitor | CRITICAL | health_monitor.py:139 | _handle_critical_failure | üö® CRITICAL: Health check bot_connection failed 16 times
2025-08-11 16:43:35 | RepitBot.HealthMonitor | CRITICAL | health_monitor.py:139 | _handle_critical_failure | üö® CRITICAL: Health check bot_connection failed 18 times
2025-08-11 16:43:40 | RepitBot.HealthMonitor | ERROR    | health_monitor.py:174 | _recover_bot_connection | ‚ùå Failed to recover bot connection: httpx.ConnectError: 
2025-08-11 16:43:40 | RepitBot.HealthMonitor | ERROR    | health_monitor.py:174 | _recover_bot_connection | ‚ùå Failed to recover bot connection: httpx.ConnectError: 
2025-08-11 16:45:35 | RepitBot.HealthMonitor | CRITICAL | health_monitor.py:139 | _handle_critical_failure | üö® CRITICAL: Health check bot_connection failed 17 times
2025-08-11 16:45:35 | RepitBot.HealthMonitor | CRITICAL | health_monitor.py:139 | _handle_critical_failure | üö® CRITICAL: Health check bot_connection failed 19 times
2025-08-11 16:45:40 | RepitBot.HealthMonitor | ERROR    | health_monitor.py:174 | _recover_bot_connection | ‚ùå Failed to recover bot connection: httpx.ConnectError: 
2025-08-11 16:45:40 | RepitBot.HealthMonitor | ERROR    | health_monitor.py:174 | _recover_bot_connection | ‚ùå Failed to recover bot connection: httpx.ConnectError: 
2025-08-11 16:47:35 | RepitBot.HealthMonitor | CRITICAL | health_monitor.py:139 | _handle_critical_failure | üö® CRITICAL: Health check bot_connection failed 18 times
2025-08-11 16:47:35 | RepitBot.HealthMonitor | CRITICAL | health_monitor.py:139 | _handle_critical_failure | üö® CRITICAL: Health check bot_connection failed 20 times
2025-08-11 16:47:40 | RepitBot.HealthMonitor | ERROR    | health_monitor.py:174 | _recover_bot_connection | ‚ùå Failed to recover bot connection: httpx.ConnectError: 
2025-08-11 16:47:40 | RepitBot.HealthMonitor | ERROR    | health_monitor.py:174 | _recover_bot_connection | ‚ùå Failed to recover bot connection: httpx.ConnectError: 
2025-08-11 16:49:35 | RepitBot.HealthMonitor | CRITICAL | health_monitor.py:139 | _handle_critical_failure | üö® CRITICAL: Health check bot_connection failed 19 times
2025-08-11 16:49:35 | RepitBot.HealthMonitor | CRITICAL | health_monitor.py:139 | _handle_critical_failure | üö® CRITICAL: Health check bot_connection failed 21 times
2025-08-11 16:49:40 | RepitBot.HealthMonitor | ERROR    | health_monitor.py:174 | _recover_bot_connection | ‚ùå Failed to recover bot connection: httpx.ConnectError: 
2025-08-11 16:49:40 | RepitBot.HealthMonitor | ERROR    | health_monitor.py:174 | _recover_bot_connection | ‚ùå Failed to recover bot connection: httpx.ConnectError: 
2025-08-11 16:51:35 | RepitBot.HealthMonitor | CRITICAL | health_monitor.py:139 | _handle_critical_failure | üö® CRITICAL: Health check bot_connection failed 20 times
2025-08-11 16:51:35 | RepitBot.HealthMonitor | CRITICAL | health_monitor.py:139 | _handle_critical_failure | üö® CRITICAL: Health check bot_connection failed 22 times
2025-08-11 16:51:40 | RepitBot.HealthMonitor | ERROR    | health_monitor.py:174 | _recover_bot_connection | ‚ùå Failed to recover bot connection: httpx.ConnectError: 
2025-08-11 16:51:40 | RepitBot.HealthMonitor | ERROR    | health_monitor.py:174 | _recover_bot_connection | ‚ùå Failed to recover bot connection: httpx.ConnectError: 
2025-08-11 16:53:35 | RepitBot.HealthMonitor | CRITICAL | health_monitor.py:139 | _handle_critical_failure | üö® CRITICAL: Health check bot_connection failed 21 times
2025-08-11 16:53:35 | RepitBot.HealthMonitor | CRITICAL | health_monitor.py:139 | _handle_critical_failure | üö® CRITICAL: Health check bot_connection failed 23 times
2025-08-11 16:53:40 | RepitBot.HealthMonitor | ERROR    | health_monitor.py:174 | _recover_bot_connection | ‚ùå Failed to recover bot connection: httpx.ConnectError: 
2025-08-11 16:53:40 | RepitBot.HealthMonitor | ERROR    | health_monitor.py:174 | _recover_bot_connection | ‚ùå Failed to recover bot connection: httpx.ConnectError: 
2025-08-11 16:55:35 | RepitBot.HealthMonitor | CRITICAL | health_monitor.py:139 | _handle_critical_failure | üö® CRITICAL: Health check bot_connection failed 22 times
2025-08-11 16:55:36 | RepitBot.HealthMonitor | CRITICAL | health_monitor.py:139 | _handle_critical_failure | üö® CRITICAL: Health check bot_connection failed 24 times
2025-08-11 16:55:40 | RepitBot.HealthMonitor | ERROR    | health_monitor.py:174 | _recover_bot_connection | ‚ùå Failed to recover bot connection: httpx.ConnectError: 
2025-08-11 16:55:41 | RepitBot.HealthMonitor | ERROR    | health_monitor.py:174 | _recover_bot_connection | ‚ùå Failed to recover bot connection: httpx.ConnectError: 
2025-08-11 16:57:36 | RepitBot.HealthMonitor | CRITICAL | health_monitor.py:139 | _handle_critical_failure | üö® CRITICAL: Health check bot_connection failed 23 times
2025-08-11 16:57:36 | RepitBot.HealthMonitor | CRITICAL | health_monitor.py:139 | _handle_critical_failure | üö® CRITICAL: Health check bot_connection failed 25 times
2025-08-11 16:57:41 | RepitBot.HealthMonitor | ERROR    | health_monitor.py:174 | _recover_bot_connection | ‚ùå Failed to recover bot connection: httpx.ConnectError: 
2025-08-11 16:57:41 | RepitBot.HealthMonitor | ERROR    | health_monitor.py:174 | _recover_bot_connection | ‚ùå Failed to recover bot connection: httpx.ConnectError: 
2025-08-11 16:59:36 | RepitBot.HealthMonitor | CRITICAL | health_monitor.py:139 | _handle_critical_failure | üö® CRITICAL: Health check bot_connection failed 24 times
2025-08-11 16:59:36 | RepitBot.HealthMonitor | CRITICAL | health_monitor.py:139 | _handle_critical_failure | üö® CRITICAL: Health check bot_connection failed 26 times
2025-08-11 16:59:41 | RepitBot.HealthMonitor | ERROR    | health_monitor.py:174 | _recover_bot_connection | ‚ùå Failed to recover bot connection: httpx.ConnectError: 
2025-08-11 16:59:41 | RepitBot.HealthMonitor | ERROR    | health_monitor.py:174 | _recover_bot_connection | ‚ùå Failed to recover bot connection: httpx.ConnectError: 
2025-08-11 17:01:36 | RepitBot.HealthMonitor | CRITICAL | health_monitor.py:139 | _handle_critical_failure | üö® CRITICAL: Health check bot_connection failed 25 times
2025-08-11 17:01:36 | RepitBot.HealthMonitor | CRITICAL | health_monitor.py:139 | _handle_critical_failure | üö® CRITICAL: Health check bot_connection failed 27 times
2025-08-11 17:01:41 | RepitBot.HealthMonitor | ERROR    | health_monitor.py:174 | _recover_bot_connection | ‚ùå Failed to recover bot connection: httpx.ConnectError: 
2025-08-11 17:01:41 | RepitBot.HealthMonitor | ERROR    | health_monitor.py:174 | _recover_bot_connection | ‚ùå Failed to recover bot connection: httpx.ConnectError: 
2025-08-11 17:03:36 | RepitBot.HealthMonitor | CRITICAL | health_monitor.py:139 | _handle_critical_failure | üö® CRITICAL: Health check bot_connection failed 26 times
2025-08-11 17:03:36 | RepitBot.HealthMonitor | CRITICAL | health_monitor.py:139 | _handle_critical_failure | üö® CRITICAL: Health check bot_connection failed 28 times
2025-08-11 17:03:41 | RepitBot.HealthMonitor | ERROR    | health_monitor.py:174 | _recover_bot_connection | ‚ùå Failed to recover bot connection: httpx.ConnectError: 
2025-08-11 17:03:41 | RepitBot.HealthMonitor | ERROR    | health_monitor.py:174 | _recover_bot_connection | ‚ùå Failed to recover bot connection: httpx.ConnectError: 
2025-08-14 14:56:56 | RepitBot | ERROR    | logger.py:228 | log_telegram_error | Telegram error: {'error_type': 'Global Error Handler', 'user_id': 7722156884, 'message': 'Callback: parent_child_6', 'error': 'Message is not modified: specified new message content and reply markup are exactly the same as a current content and reply markup of the message'}
2025-08-14 14:56:57 | RepitBot | ERROR    | logger.py:228 | log_telegram_error | Telegram error: {'error_type': 'Global Error Handler', 'user_id': 7722156884, 'message': 'Callback: parent_child_6', 'error': 'Message is not modified: specified new message content and reply markup are exactly the same as a current content and reply markup of the message'}
2025-08-14 15:31:19 | RepitBot | ERROR    | logger.py:228 | log_telegram_error | Telegram error: {'error_type': 'Global Error Handler', 'user_id': 7722156884, 'message': 'Callback: parent_child_6', 'error': 'There is no text in the message to edit'}
2025-08-14 15:31:19 | RepitBot | ERROR    | logger.py:228 | log_telegram_error | Telegram error: {'error_type': 'Global Error Handler', 'user_id': 7722156884, 'message': 'Callback: parent_child_6', 'error': 'There is no text in the message to edit'}
2025-08-14 15:31:22 | RepitBot | ERROR    | logger.py:228 | log_telegram_error | Telegram error: {'error_type': 'Global Error Handler', 'user_id': 7722156884, 'message': 'Callback: parent_child_6', 'error': 'There is no text in the message to edit'}
2025-08-14 15:41:25 | RepitBot | ERROR    | logger.py:228 | log_telegram_error | Telegram error: {'error_type': 'Global Error Handler', 'user_id': 7722156884, 'message': 'Callback: parent_chart_6', 'error': 'Message to edit not found'}
2025-08-14 15:41:26 | RepitBot | ERROR    | logger.py:228 | log_telegram_error | Telegram error: {'error_type': 'Global Error Handler', 'user_id': 7722156884, 'message': 'Callback: parent_chart_6', 'error': 'Message to edit not found'}
2025-08-14 15:41:39 | RepitBot | ERROR    | logger.py:228 | log_telegram_error | Telegram error: {'error_type': 'Global Error Handler', 'user_id': 7722156884, 'message': 'Callback: parent_child_6', 'error': 'There is no text in the message to edit'}
2025-08-14 15:41:42 | RepitBot | ERROR    | logger.py:228 | log_telegram_error | Telegram error: {'error_type': 'Global Error Handler', 'user_id': 7722156884, 'message': 'Callback: parent_child_6', 'error': 'There is no text in the message to edit'}
2025-08-14 15:42:30 | RepitBot | ERROR    | logger.py:228 | log_telegram_error | Telegram error: {'error_type': 'Global Error Handler', 'user_id': 7722156884, 'message': 'Callback: parent_child_6', 'error': 'There is no text in the message to edit'}
2025-08-14 16:10:10 | RepitBot | ERROR    | logger.py:228 | log_telegram_error | Telegram error: {'error_type': 'Global Error Handler', 'user_id': 8092298631, 'message': 'Callback: student_view_material_2', 'error': 'Message is not modified: specified new message content and reply markup are exactly the same as a current content and reply markup of the message'}
2025-08-14 16:25:34 | RepitBot.HealthMonitor | ERROR    | health_monitor.py:83 | run_check | Health check bot_connection timeout after 10s
2025-08-14 16:25:34 | RepitBot.HealthMonitor | CRITICAL | health_monitor.py:139 | _handle_critical_failure | üö® CRITICAL: Health check bot_connection failed 2 times
2025-08-14 16:25:39 | RepitBot.HealthMonitor | ERROR    | health_monitor.py:174 | _recover_bot_connection | ‚ùå Failed to recover bot connection: httpx.ConnectError: [Errno 11001] getaddrinfo failed
2025-08-14 16:26:39 | RepitBot | ERROR    | logger.py:228 | log_telegram_error | Telegram error: {'error_type': 'Global Error Handler', 'user_id': None, 'message': None, 'error': 'httpx.ConnectError: [Errno 11001] getaddrinfo failed'}
2025-08-14 16:27:10 | RepitBot | ERROR    | logger.py:228 | log_telegram_error | Telegram error: {'error_type': 'Global Error Handler', 'user_id': None, 'message': None, 'error': 'httpx.ConnectError: [Errno 11001] getaddrinfo failed'}
2025-08-14 16:27:37 | RepitBot.HealthMonitor | CRITICAL | health_monitor.py:139 | _handle_critical_failure | üö® CRITICAL: Health check bot_connection failed 3 times
2025-08-14 16:27:48 | RepitBot.HealthMonitor | ERROR    | health_monitor.py:174 | _recover_bot_connection | ‚ùå Failed to recover bot connection: httpx.ConnectError: [Errno 11001] getaddrinfo failed
2025-08-14 16:29:06 | RepitBot | ERROR    | logger.py:228 | log_telegram_error | Telegram error: {'error_type': 'Global Error Handler', 'user_id': None, 'message': None, 'error': 'httpx.ConnectError: [Errno 11001] getaddrinfo failed'}
2025-08-14 16:29:48 | RepitBot.HealthMonitor | ERROR    | health_monitor.py:83 | run_check | Health check bot_connection timeout after 10s
2025-08-14 16:29:48 | RepitBot.HealthMonitor | CRITICAL | health_monitor.py:139 | _handle_critical_failure | üö® CRITICAL: Health check bot_connection failed 4 times
2025-08-14 16:29:48 | RepitBot | ERROR    | logger.py:228 | log_telegram_error | Telegram error: {'error_type': 'Global Error Handler', 'user_id': None, 'message': None, 'error': 'httpx.ConnectError: [Errno 11001] getaddrinfo failed'}
2025-08-14 16:29:58 | RepitBot.HealthMonitor | ERROR    | health_monitor.py:174 | _recover_bot_connection | ‚ùå Failed to recover bot connection: httpx.ConnectError: [Errno 11001] getaddrinfo failed
2025-08-14 16:30:50 | RepitBot | ERROR    | logger.py:228 | log_telegram_error | Telegram error: {'error_type': 'Global Error Handler', 'user_id': None, 'message': None, 'error': 'httpx.ConnectError: [Errno 11001] getaddrinfo failed'}
2025-08-14 16:31:47 | RepitBot.HealthMonitor | CRITICAL | health_monitor.py:139 | _handle_critical_failure | üö® CRITICAL: Health check bot_connection failed 5 times
2025-08-14 16:31:51 | RepitBot | ERROR    | logger.py:228 | log_telegram_error | Telegram error: {'error_type': 'Global Error Handler', 'user_id': None, 'message': None, 'error': 'httpx.ConnectError: [Errno 11001] getaddrinfo failed'}
2025-08-14 16:31:58 | RepitBot.HealthMonitor | ERROR    | health_monitor.py:174 | _recover_bot_connection | ‚ùå Failed to recover bot connection: httpx.ConnectError: [Errno 11001] getaddrinfo failed
2025-08-14 16:32:32 | RepitBot | ERROR    | logger.py:228 | log_telegram_error | Telegram error: {'error_type': 'Global Error Handler', 'user_id': None, 'message': None, 'error': 'httpx.ConnectError: [Errno 11001] getaddrinfo failed'}
2025-08-14 16:33:58 | RepitBot.HealthMonitor | ERROR    | health_monitor.py:83 | run_check | Health check bot_connection timeout after 10s
2025-08-14 16:33:58 | RepitBot.HealthMonitor | CRITICAL | health_monitor.py:139 | _handle_critical_failure | üö® CRITICAL: Health check bot_connection failed 6 times
2025-08-14 16:34:03 | RepitBot.HealthMonitor | ERROR    | health_monitor.py:174 | _recover_bot_connection | ‚ùå Failed to recover bot connection: httpx.ConnectError: [Errno 11001] getaddrinfo failed
2025-08-14 16:35:18 | RepitBot | ERROR    | logger.py:228 | log_telegram_error | Telegram error: {'error_type': 'Global Error Handler', 'user_id': None, 'message': None, 'error': 'httpx.ConnectError: [Errno 11001] getaddrinfo failed'}
2025-08-14 16:35:49 | RepitBot | ERROR    | logger.py:228 | log_telegram_error | Telegram error: {'error_type': 'Global Error Handler', 'user_id': None, 'message': None, 'error': 'httpx.ConnectError: [Errno 11001] getaddrinfo failed'}
2025-08-14 16:36:01 | RepitBot.HealthMonitor | CRITICAL | health_monitor.py:139 | _handle_critical_failure | üö® CRITICAL: Health check bot_connection failed 7 times
2025-08-14 16:36:12 | RepitBot.HealthMonitor | ERROR    | health_monitor.py:174 | _recover_bot_connection | ‚ùå Failed to recover bot connection: httpx.ConnectError: [Errno 11001] getaddrinfo failed
2025-08-14 16:36:30 | RepitBot | ERROR    | logger.py:228 | log_telegram_error | Telegram error: {'error_type': 'Global Error Handler', 'user_id': None, 'message': None, 'error': 'httpx.ConnectError: [Errno 11001] getaddrinfo failed'}
2025-08-14 16:38:01 | RepitBot | ERROR    | logger.py:228 | log_telegram_error | Telegram error: {'error_type': 'Global Error Handler', 'user_id': None, 'message': None, 'error': 'httpx.ConnectError: [Errno 11001] getaddrinfo failed'}
2025-08-14 16:38:12 | RepitBot.HealthMonitor | ERROR    | health_monitor.py:83 | run_check | Health check bot_connection timeout after 10s
2025-08-14 16:38:12 | RepitBot.HealthMonitor | CRITICAL | health_monitor.py:139 | _handle_critical_failure | üö® CRITICAL: Health check bot_connection failed 8 times
2025-08-14 16:38:22 | RepitBot.HealthMonitor | ERROR    | health_monitor.py:174 | _recover_bot_connection | ‚ùå Failed to recover bot connection: httpx.ConnectError: [Errno 11001] getaddrinfo failed
2025-08-14 16:39:03 | RepitBot | ERROR    | logger.py:228 | log_telegram_error | Telegram error: {'error_type': 'Global Error Handler', 'user_id': None, 'message': None, 'error': 'httpx.ConnectError: [Errno 11001] getaddrinfo failed'}
2025-08-14 16:39:34 | RepitBot | ERROR    | logger.py:228 | log_telegram_error | Telegram error: {'error_type': 'Global Error Handler', 'user_id': None, 'message': None, 'error': 'httpx.ConnectError: [Errno 11001] getaddrinfo failed'}
2025-08-14 16:40:11 | RepitBot.HealthMonitor | CRITICAL | health_monitor.py:139 | _handle_critical_failure | üö® CRITICAL: Health check bot_connection failed 9 times
2025-08-14 16:40:11 | RepitBot | ERROR    | logger.py:228 | log_telegram_error | Telegram error: {'error_type': 'Global Error Handler', 'user_id': None, 'message': None, 'error': 'httpx.ConnectError: [Errno 11001] getaddrinfo failed'}
2025-08-14 16:40:23 | RepitBot.HealthMonitor | ERROR    | health_monitor.py:174 | _recover_bot_connection | ‚ùå Failed to recover bot connection: httpx.ConnectError: [Errno 11001] getaddrinfo failed
2025-08-14 16:40:23 | RepitBot | ERROR    | logger.py:228 | log_telegram_error | Telegram error: {'error_type': 'Global Error Handler', 'user_id': None, 'message': None, 'error': 'httpx.ConnectError: [Errno 11001] getaddrinfo failed'}
2025-08-14 16:40:24 | RepitBot | ERROR    | logger.py:228 | log_telegram_error | Telegram error: {'error_type': 'Global Error Handler', 'user_id': None, 'message': None, 'error': 'httpx.ConnectError: [Errno 11001] getaddrinfo failed'}
2025-08-14 16:40:26 | RepitBot | ERROR    | logger.py:228 | log_telegram_error | Telegram error: {'error_type': 'Global Error Handler', 'user_id': None, 'message': None, 'error': 'httpx.ConnectError: [Errno 11001] getaddrinfo failed'}
2025-08-14 16:40:28 | RepitBot | ERROR    | logger.py:228 | log_telegram_error | Telegram error: {'error_type': 'Global Error Handler', 'user_id': None, 'message': None, 'error': 'httpx.ConnectError: [Errno 11001] getaddrinfo failed'}
2025-08-14 16:40:33 | RepitBot | ERROR    | logger.py:228 | log_telegram_error | Telegram error: {'error_type': 'Global Error Handler', 'user_id': None, 'message': None, 'error': 'httpx.ConnectError: [Errno 11001] getaddrinfo failed'}
2025-08-14 16:40:40 | RepitBot | ERROR    | logger.py:228 | log_telegram_error | Telegram error: {'error_type': 'Global Error Handler', 'user_id': None, 'message': None, 'error': 'httpx.ConnectError: [Errno 11001] getaddrinfo failed'}
2025-08-14 16:40:47 | RepitBot | ERROR    | logger.py:228 | log_telegram_error | Telegram error: {'error_type': 'Global Error Handler', 'user_id': None, 'message': None, 'error': 'httpx.ConnectError: [Errno 11001] getaddrinfo failed'}
2025-08-14 16:41:01 | RepitBot | ERROR    | logger.py:228 | log_telegram_error | Telegram error: {'error_type': 'Global Error Handler', 'user_id': None, 'message': None, 'error': 'httpx.ConnectError: [Errno 11001] getaddrinfo failed'}
2025-08-14 16:41:22 | RepitBot | ERROR    | logger.py:228 | log_telegram_error | Telegram error: {'error_type': 'Global Error Handler', 'user_id': None, 'message': None, 'error': 'httpx.ConnectError: [Errno 11001] getaddrinfo failed'}
2025-08-14 17:14:51 | RepitBot | ERROR    | logger.py:228 | log_telegram_error | Telegram error: {'error_type': 'Global Error Handler', 'user_id': None, 'message': None, 'error': 'httpx.ReadError: '}
2025-08-14 17:14:52 | RepitBot | ERROR    | logger.py:228 | log_telegram_error | Telegram error: {'error_type': 'Global Error Handler', 'user_id': None, 'message': None, 'error': 'httpx.ConnectError: [Errno 11001] getaddrinfo failed'}
2025-08-14 17:14:54 | RepitBot | ERROR    | logger.py:228 | log_telegram_error | Telegram error: {'error_type': 'Global Error Handler', 'user_id': None, 'message': None, 'error': 'httpx.ConnectError: [Errno 11001] getaddrinfo failed'}
2025-08-14 17:14:56 | RepitBot | ERROR    | logger.py:228 | log_telegram_error | Telegram error: {'error_type': 'Global Error Handler', 'user_id': None, 'message': None, 'error': 'httpx.ConnectError: [Errno 11001] getaddrinfo failed'}
2025-08-14 17:14:59 | RepitBot | ERROR    | logger.py:228 | log_telegram_error | Telegram error: {'error_type': 'Global Error Handler', 'user_id': None, 'message': None, 'error': 'httpx.ConnectError: [Errno 11001] getaddrinfo failed'}
2025-08-14 17:15:37 | RepitBot | ERROR    | logger.py:228 | log_telegram_error | Telegram error: {'error_type': 'Global Error Handler', 'user_id': None, 'message': None, 'error': 'httpx.ReadError: '}
2025-08-14 17:15:38 | RepitBot | ERROR    | logger.py:228 | log_telegram_error | Telegram error: {'error_type': 'Global Error Handler', 'user_id': None, 'message': None, 'error': 'httpx.ConnectError: [Errno 11001] getaddrinfo failed'}
2025-08-14 17:15:40 | RepitBot | ERROR    | logger.py:228 | log_telegram_error | Telegram error: {'error_type': 'Global Error Handler', 'user_id': None, 'message': None, 'error': 'httpx.ConnectError: [Errno 11001] getaddrinfo failed'}
2025-08-14 17:15:42 | RepitBot | ERROR    | logger.py:228 | log_telegram_error | Telegram error: {'error_type': 'Global Error Handler', 'user_id': None, 'message': None, 'error': 'httpx.ConnectError: [Errno 11001] getaddrinfo failed'}
2025-08-14 17:15:56 | RepitBot | ERROR    | logger.py:228 | log_telegram_error | Telegram error: {'error_type': 'Global Error Handler', 'user_id': None, 'message': None, 'error': 'httpx.ReadError: '}
2025-08-14 17:16:01 | RepitBot | ERROR    | logger.py:228 | log_telegram_error | Telegram error: {'error_type': 'Global Error Handler', 'user_id': None, 'message': None, 'error': 'httpx.ConnectError: [Errno 11001] getaddrinfo failed'}
2025-08-14 17:16:08 | RepitBot | ERROR    | logger.py:228 | log_telegram_error | Telegram error: {'error_type': 'Global Error Handler', 'user_id': None, 'message': None, 'error': 'httpx.ConnectError: [Errno 11001] getaddrinfo failed'}
2025-08-14 17:16:59 | RepitBot | ERROR    | logger.py:228 | log_telegram_error | Telegram error: {'error_type': 'Global Error Handler', 'user_id': None, 'message': None, 'error': 'httpx.ReadError: '}
2025-08-14 17:17:00 | RepitBot | ERROR    | logger.py:228 | log_telegram_error | Telegram error: {'error_type': 'Global Error Handler', 'user_id': None, 'message': None, 'error': 'httpx.ConnectError: [Errno 11001] getaddrinfo failed'}
2025-08-14 17:17:08 | RepitBot | ERROR    | logger.py:228 | log_telegram_error | Telegram error: {'error_type': 'Global Error Handler', 'user_id': None, 'message': None, 'error': 'httpx.ConnectError: [Errno 11001] getaddrinfo failed'}
2025-08-14 17:17:15 | RepitBot | ERROR    | logger.py:228 | log_telegram_error | Telegram error: {'error_type': 'Global Error Handler', 'user_id': None, 'message': None, 'error': 'httpx.ConnectError: [Errno 11001] getaddrinfo failed'}
2025-08-14 17:17:22 | RepitBot | ERROR    | logger.py:228 | log_telegram_error | Telegram error: {'error_type': 'Global Error Handler', 'user_id': None, 'message': None, 'error': 'httpx.ConnectError: [Errno 11001] getaddrinfo failed'}
2025-08-14 17:21:18 | RepitBot | ERROR    | logger.py:228 | log_telegram_error | Telegram error: {'error_type': 'Global Error Handler', 'user_id': None, 'message': None, 'error': 'httpx.ConnectError: [Errno 11001] getaddrinfo failed'}
2025-08-14 17:21:19 | RepitBot | ERROR    | logger.py:228 | log_telegram_error | Telegram error: {'error_type': 'Global Error Handler', 'user_id': None, 'message': None, 'error': 'httpx.ConnectError: [Errno 11001] getaddrinfo failed'}
2025-08-14 17:55:05 | RepitBot | ERROR    | logger.py:228 | log_telegram_error | Telegram error: {'error_type': 'Global Error Handler', 'user_id': None, 'message': None, 'error': 'httpx.ConnectError: [Errno 11001] getaddrinfo failed'}
2025-08-14 17:55:06 | RepitBot | ERROR    | logger.py:228 | log_telegram_error | Telegram error: {'error_type': 'Global Error Handler', 'user_id': None, 'message': None, 'error': 'httpx.ConnectError: [Errno 11001] getaddrinfo failed'}
2025-08-14 17:55:08 | RepitBot | ERROR    | logger.py:228 | log_telegram_error | Telegram error: {'error_type': 'Global Error Handler', 'user_id': None, 'message': None, 'error': 'httpx.ConnectError: [Errno 11001] getaddrinfo failed'}
2025-08-14 18:01:26 | RepitBot | ERROR    | logger.py:228 | log_telegram_error | Telegram error: {'error_type': 'Global Error Handler', 'user_id': None, 'message': None, 'error': 'httpx.ConnectError: [Errno 11001] getaddrinfo failed'}
2025-08-14 18:01:26 | RepitBot.HealthMonitor | CRITICAL | health_monitor.py:139 | _handle_critical_failure | üö® CRITICAL: Health check bot_connection failed 3 times
2025-08-14 18:01:26 | RepitBot.HealthMonitor | ERROR    | health_monitor.py:174 | _recover_bot_connection | ‚ùå Failed to recover bot connection: httpx.ConnectError: [Errno 11001] getaddrinfo failed
2025-08-14 18:31:58 | RepitBot | ERROR    | logger.py:228 | log_telegram_error | Telegram error: {'error_type': 'Global Error Handler', 'user_id': None, 'message': None, 'error': 'httpx.ConnectError: [Errno 11001] getaddrinfo failed'}
2025-08-14 18:31:59 | RepitBot.HealthMonitor | CRITICAL | health_monitor.py:139 | _handle_critical_failure | üö® CRITICAL: Health check bot_connection failed 4 times
2025-08-14 18:31:59 | RepitBot.HealthMonitor | ERROR    | health_monitor.py:174 | _recover_bot_connection | ‚ùå Failed to recover bot connection: httpx.ConnectError: [Errno 11001] getaddrinfo failed
2025-08-14 18:32:03 | RepitBot | ERROR    | logger.py:228 | log_telegram_error | Telegram error: {'error_type': 'Global Error Handler', 'user_id': None, 'message': None, 'error': 'httpx.ConnectError: [Errno 11001] getaddrinfo failed'}
2025-08-14 18:34:09 | RepitBot.HealthMonitor | ERROR    | health_monitor.py:83 | run_check | Health check bot_connection timeout after 10s
2025-08-14 18:34:09 | RepitBot.HealthMonitor | CRITICAL | health_monitor.py:139 | _handle_critical_failure | üö® CRITICAL: Health check bot_connection failed 5 times
2025-08-14 18:34:31 | RepitBot.HealthMonitor | ERROR    | health_monitor.py:174 | _recover_bot_connection | ‚ùå Failed to recover bot connection: httpx.ConnectError: 
2025-08-14 18:36:11 | RepitBot.HealthMonitor | ERROR    | health_monitor.py:83 | run_check | Health check bot_connection timeout after 10s
2025-08-14 18:36:11 | RepitBot.HealthMonitor | CRITICAL | health_monitor.py:139 | _handle_critical_failure | üö® CRITICAL: Health check bot_connection failed 6 times
2025-08-14 18:36:41 | RepitBot.HealthMonitor | ERROR    | health_monitor.py:174 | _recover_bot_connection | ‚ùå Failed to recover bot connection: Timed out
2025-08-14 18:38:11 | RepitBot.HealthMonitor | ERROR    | health_monitor.py:83 | run_check | Health check bot_connection timeout after 10s
2025-08-14 18:38:11 | RepitBot.HealthMonitor | CRITICAL | health_monitor.py:139 | _handle_critical_failure | üö® CRITICAL: Health check bot_connection failed 7 times
2025-08-14 18:38:31 | RepitBot.HealthMonitor | ERROR    | health_monitor.py:174 | _recover_bot_connection | ‚ùå Failed to recover bot connection: httpx.ConnectError: 
2025-08-14 18:40:21 | RepitBot.HealthMonitor | ERROR    | health_monitor.py:83 | run_check | Health check bot_connection timeout after 10s
2025-08-14 18:40:21 | RepitBot.HealthMonitor | CRITICAL | health_monitor.py:139 | _handle_critical_failure | üö® CRITICAL: Health check bot_connection failed 8 times
2025-08-14 18:41:04 | RepitBot | ERROR    | bot.py:377 | main | –ö—Ä–∏—Ç–∏—á–µ—Å–∫–∞—è –æ—à–∏–±–∫–∞ –ø—Ä–∏ –∑–∞–ø—É—Å–∫–µ –±–æ—Ç–∞: httpx.ConnectError: 
2025-08-14 18:51:27 | RepitBot | ERROR    | logger.py:228 | log_telegram_error | Telegram error: {'error_type': 'Global Error Handler', 'user_id': None, 'message': None, 'error': 'httpx.ReadError: '}
2025-08-14 18:51:40 | RepitBot | ERROR    | logger.py:228 | log_telegram_error | Telegram error: {'error_type': 'Global Error Handler', 'user_id': None, 'message': None, 'error': 'httpx.ConnectError: [Errno 11001] getaddrinfo failed'}
2025-08-14 18:51:53 | RepitBot | ERROR    | logger.py:228 | log_telegram_error | Telegram error: {'error_type': 'Global Error Handler', 'user_id': None, 'message': None, 'error': 'httpx.ConnectError: [Errno 11001] getaddrinfo failed'}
2025-08-14 18:52:06 | RepitBot | ERROR    | logger.py:228 | log_telegram_error | Telegram error: {'error_type': 'Global Error Handler', 'user_id': None, 'message': None, 'error': 'httpx.ConnectError: [Errno 11001] getaddrinfo failed'}
2025-08-14 21:49:36 | RepitBot | ERROR    | logger.py:228 | log_telegram_error | Telegram error: {'error_type': 'Global Error Handler', 'user_id': None, 'message': None, 'error': 'httpx.ConnectError: [Errno 11001] getaddrinfo failed'}
2025-08-14 21:49:37 | RepitBot | ERROR    | logger.py:228 | log_telegram_error | Telegram error: {'error_type': 'Global Error Handler', 'user_id': None, 'message': None, 'error': 'httpx.ConnectError: [Errno 11001] getaddrinfo failed'}
2025-08-14 21:49:38 | RepitBot | ERROR    | logger.py:228 | log_telegram_error | Telegram error: {'error_type': 'Global Error Handler', 'user_id': None, 'message': None, 'error': 'httpx.ConnectError: [Errno 11001] getaddrinfo failed'}
2025-08-14 21:52:12 | RepitBot | ERROR    | logger.py:228 | log_telegram_error | Telegram error: {'error_type': 'Global Error Handler', 'user_id': None, 'message': None, 'error': 'httpx.ConnectError: [Errno 11001] getaddrinfo failed'}
2025-08-14 22:13:39 | RepitBot.HealthMonitor | CRITICAL | health_monitor.py:139 | _handle_critical_failure | üö® CRITICAL: Health check bot_connection failed 3 times
2025-08-14 22:13:39 | RepitBot | ERROR    | logger.py:228 | log_telegram_error | Telegram error: {'error_type': 'Global Error Handler', 'user_id': None, 'message': None, 'error': 'httpx.ConnectError: [Errno 11001] getaddrinfo failed'}
2025-08-14 22:13:39 | RepitBot.HealthMonitor | ERROR    | health_monitor.py:174 | _recover_bot_connection | ‚ùå Failed to recover bot connection: httpx.ConnectError: [Errno 11001] getaddrinfo failed
2025-08-14 22:13:40 | RepitBot | ERROR    | logger.py:228 | log_telegram_error | Telegram error: {'error_type': 'Global Error Handler', 'user_id': None, 'message': None, 'error': 'httpx.ConnectError: [Errno 11001] getaddrinfo failed'}
2025-08-14 22:13:41 | RepitBot | ERROR    | logger.py:228 | log_telegram_error | Telegram error: {'error_type': 'Global Error Handler', 'user_id': None, 'message': None, 'error': 'httpx.ConnectError: [Errno 11001] getaddrinfo failed'}
2025-08-14 22:59:00 | RepitBot | ERROR    | logger.py:228 | log_telegram_error | Telegram error: {'error_type': 'Global Error Handler', 'user_id': None, 'message': None, 'error': 'httpx.ConnectError: [Errno 11001] getaddrinfo failed'}
2025-08-14 22:59:01 | RepitBot.HealthMonitor | CRITICAL | health_monitor.py:139 | _handle_critical_failure | üö® CRITICAL: Health check bot_connection failed 4 times
2025-08-14 22:59:01 | RepitBot.HealthMonitor | ERROR    | health_monitor.py:174 | _recover_bot_connection | ‚ùå Failed to recover bot connection: httpx.ConnectError: [Errno 11001] getaddrinfo failed
2025-08-14 22:59:09 | RepitBot | ERROR    | logger.py:228 | log_telegram_error | Telegram error: {'error_type': 'Global Error Handler', 'user_id': None, 'message': None, 'error': 'httpx.ConnectError: [Errno 11001] getaddrinfo failed'}
2025-08-15 02:07:45 | RepitBot | ERROR    | logger.py:228 | log_telegram_error | Telegram error: {'error_type': 'Global Error Handler', 'user_id': None, 'message': None, 'error': 'httpx.ConnectError: [Errno 11001] getaddrinfo failed'}
2025-08-15 02:07:45 | RepitBot.HealthMonitor | CRITICAL | health_monitor.py:139 | _handle_critical_failure | üö® CRITICAL: Health check bot_connection failed 5 times
2025-08-15 02:07:45 | RepitBot.HealthMonitor | ERROR    | health_monitor.py:174 | _recover_bot_connection | ‚ùå Failed to recover bot connection: httpx.ConnectError: [Errno 11001] getaddrinfo failed
2025-08-15 02:07:48 | RepitBot | ERROR    | logger.py:228 | log_telegram_error | Telegram error: {'error_type': 'Global Error Handler', 'user_id': None, 'message': None, 'error': 'httpx.ConnectError: [Errno 11001] getaddrinfo failed'}
2025-08-15 02:07:50 | RepitBot | ERROR    | logger.py:228 | log_telegram_error | Telegram error: {'error_type': 'Global Error Handler', 'user_id': None, 'message': None, 'error': 'httpx.ConnectError: [Errno 11001] getaddrinfo failed'}
2025-08-15 02:07:54 | RepitBot | ERROR    | logger.py:228 | log_telegram_error | Telegram error: {'error_type': 'Global Error Handler', 'user_id': None, 'message': None, 'error': 'httpx.ConnectError: [Errno 11001] getaddrinfo failed'}
2025-08-15 02:07:59 | RepitBot | ERROR    | logger.py:228 | log_telegram_error | Telegram error: {'error_type': 'Global Error Handler', 'user_id': None, 'message': None, 'error': 'httpx.ConnectError: [Errno 11001] getaddrinfo failed'}
2025-08-15 02:08:07 | RepitBot | ERROR    | logger.py:228 | log_telegram_error | Telegram error: {'error_type': 'Global Error Handler', 'user_id': None, 'message': None, 'error': 'httpx.ConnectError: [Errno 11001] getaddrinfo failed'}
2025-08-15 02:08:30 | RepitBot | ERROR    | logger.py:228 | log_telegram_error | Telegram error: {'error_type': 'Global Error Handler', 'user_id': None, 'message': None, 'error': 'httpx.ConnectError: [Errno 11001] getaddrinfo failed'}
2025-08-15 02:08:46 | RepitBot | ERROR    | logger.py:228 | log_telegram_error | Telegram error: {'error_type': 'Global Error Handler', 'user_id': None, 'message': None, 'error': 'httpx.ConnectError: [Errno 11001] getaddrinfo failed'}
2025-08-15 02:08:47 | RepitBot | ERROR    | logger.py:228 | log_telegram_error | Telegram error: {'error_type': 'Global Error Handler', 'user_id': None, 'message': None, 'error': 'httpx.ConnectError: [Errno 11001] getaddrinfo failed'}
2025-08-15 02:08:49 | RepitBot | ERROR    | logger.py:228 | log_telegram_error | Telegram error: {'error_type': 'Global Error Handler', 'user_id': None, 'message': None, 'error': 'httpx.ConnectError: [Errno 11001] getaddrinfo failed'}
2025-08-22 17:05:48 | RepitBot | ERROR    | bot.py:165 | initialize_systems | ‚ùå –û—à–∏–±–∫–∞ –ø—Ä–∏ –∏–Ω–∏—Ü–∏–∞–ª–∏–∑–∞—Ü–∏–∏ —Å–∏—Å—Ç–µ–º: httpx.ConnectError: [Errno 11001] getaddrinfo failed
2025-08-22 17:05:48 | RepitBot | ERROR    | bot.py:409 | main | –ö—Ä–∏—Ç–∏—á–µ—Å–∫–∞—è –æ—à–∏–±–∫–∞ –ø—Ä–∏ –∑–∞–ø—É—Å–∫–µ –±–æ—Ç–∞: httpx.ConnectError: [Errno 11001] getaddrinfo failed
2025-08-22 17:06:29 | RepitBot | ERROR    | bot.py:165 | initialize_systems | ‚ùå –û—à–∏–±–∫–∞ –ø—Ä–∏ –∏–Ω–∏—Ü–∏–∞–ª–∏–∑–∞—Ü–∏–∏ —Å–∏—Å—Ç–µ–º: httpx.ConnectError: [Errno 11001] getaddrinfo failed
2025-08-22 17:06:29 | RepitBot | ERROR    | bot.py:409 | main | –ö—Ä–∏—Ç–∏—á–µ—Å–∫–∞—è –æ—à–∏–±–∫–∞ –ø—Ä–∏ –∑–∞–ø—É—Å–∫–µ –±–æ—Ç–∞: httpx.ConnectError: [Errno 11001] getaddrinfo failed
2025-08-22 17:07:06 | RepitBot | ERROR    | logger.py:228 | log_telegram_error | Telegram error: {'error_type': 'Global Error Handler', 'user_id': 1229333908, 'message': 'üéì –°–ø–∏—Å–æ–∫ —É—á–µ–Ω–∏–∫–æ–≤', 'error': '(sqlite3.OperationalError) no such column: users.grade\n[SQL: SELECT users.id AS users_id, users.telegram_id AS users_telegram_id, users.username AS users_username, users.full_name AS users_full_name, users.role AS users_role, users.access_code AS users_access_code, users.grade AS users_grade, users.points AS users_points, users.streak_days AS users_streak_days, users.last_lesson_date AS users_last_lesson_date, users.total_study_hours AS users_total_study_hours, users.created_at AS users_created_at, users.parent_id AS users_parent_id \nFROM users \nWHERE users.telegram_id = ?\n LIMIT ? OFFSET ?]\n[parameters: (1229333908, 1, 0)]\n(Background on this error at: https://sqlalche.me/e/20/e3q8)'}
2025-08-22 17:07:08 | RepitBot | ERROR    | logger.py:228 | log_telegram_error | Telegram error: {'error_type': 'Global Error Handler', 'user_id': 1229333908, 'message': 'üéì –°–ø–∏—Å–æ–∫ —É—á–µ–Ω–∏–∫–æ–≤', 'error': '(sqlite3.OperationalError) no such column: users.grade\n[SQL: SELECT users.id AS users_id, users.telegram_id AS users_telegram_id, users.username AS users_username, users.full_name AS users_full_name, users.role AS users_role, users.access_code AS users_access_code, users.grade AS users_grade, users.points AS users_points, users.streak_days AS users_streak_days, users.last_lesson_date AS users_last_lesson_date, users.total_study_hours AS users_total_study_hours, users.created_at AS users_created_at, users.parent_id AS users_parent_id \nFROM users \nWHERE users.telegram_id = ?\n LIMIT ? OFFSET ?]\n[parameters: (1229333908, 1, 0)]\n(Background on this error at: https://sqlalche.me/e/20/e3q8)'}
2025-08-22 17:07:10 | RepitBot | ERROR    | logger.py:228 | log_telegram_error | Telegram error: {'error_type': 'Global Error Handler', 'user_id': 1229333908, 'message': '‚ûï –î–æ–±–∞–≤–∏—Ç—å —É—á–µ–Ω–∏–∫–∞', 'error': '(sqlite3.OperationalError) no such column: users.grade\n[SQL: SELECT users.id AS users_id, users.telegram_id AS users_telegram_id, users.username AS users_username, users.full_name AS users_full_name, users.role AS users_role, users.access_code AS users_access_code, users.grade AS users_grade, users.points AS users_points, users.streak_days AS users_streak_days, users.last_lesson_date AS users_last_lesson_date, users.total_study_hours AS users_total_study_hours, users.created_at AS users_created_at, users.parent_id AS users_parent_id \nFROM users \nWHERE users.telegram_id = ?\n LIMIT ? OFFSET ?]\n[parameters: (1229333908, 1, 0)]\n(Background on this error at: https://sqlalche.me/e/20/e3q8)'}
2025-08-22 17:07:12 | RepitBot | ERROR    | logger.py:228 | log_telegram_error | Telegram error: {'error_type': 'Global Error Handler', 'user_id': 1229333908, 'message': 'üìä –û—Ç—á—ë—Ç –∑–∞ –º–µ—Å—è—Ü', 'error': '(sqlite3.OperationalError) no such column: users.grade\n[SQL: SELECT users.id AS users_id, users.telegram_id AS users_telegram_id, users.username AS users_username, users.full_name AS users_full_name, users.role AS users_role, users.access_code AS users_access_code, users.grade AS users_grade, users.points AS users_points, users.streak_days AS users_streak_days, users.last_lesson_date AS users_last_lesson_date, users.total_study_hours AS users_total_study_hours, users.created_at AS users_created_at, users.parent_id AS users_parent_id \nFROM users \nWHERE users.telegram_id = ?\n LIMIT ? OFFSET ?]\n[parameters: (1229333908, 1, 0)]\n(Background on this error at: https://sqlalche.me/e/20/e3q8)'}
2025-08-22 17:09:50 | RepitBot | ERROR    | logger.py:228 | log_telegram_error | Telegram error: {'error_type': 'Global Error Handler', 'user_id': 1229333908, 'message': 'üéì –°–ø–∏—Å–æ–∫ —É—á–µ–Ω–∏–∫–æ–≤', 'error': '(sqlite3.OperationalError) no such column: users.grade\n[SQL: SELECT users.id AS users_id, users.telegram_id AS users_telegram_id, users.username AS users_username, users.full_name AS users_full_name, users.role AS users_role, users.access_code AS users_access_code, users.grade AS users_grade, users.points AS users_points, users.streak_days AS users_streak_days, users.last_lesson_date AS users_last_lesson_date, users.total_study_hours AS users_total_study_hours, users.created_at AS users_created_at, users.parent_id AS users_parent_id \nFROM users \nWHERE users.telegram_id = ?\n LIMIT ? OFFSET ?]\n[parameters: (1229333908, 1, 0)]\n(Background on this error at: https://sqlalche.me/e/20/e3q8)'}
2025-08-22 17:09:52 | RepitBot | ERROR    | logger.py:228 | log_telegram_error | Telegram error: {'error_type': 'Global Error Handler', 'user_id': 1229333908, 'message': 'üéì –°–ø–∏—Å–æ–∫ —É—á–µ–Ω–∏–∫–æ–≤', 'error': '(sqlite3.OperationalError) no such column: users.grade\n[SQL: SELECT users.id AS users_id, users.telegram_id AS users_telegram_id, users.username AS users_username, users.full_name AS users_full_name, users.role AS users_role, users.access_code AS users_access_code, users.grade AS users_grade, users.points AS users_points, users.streak_days AS users_streak_days, users.last_lesson_date AS users_last_lesson_date, users.total_study_hours AS users_total_study_hours, users.created_at AS users_created_at, users.parent_id AS users_parent_id \nFROM users \nWHERE users.telegram_id = ?\n LIMIT ? OFFSET ?]\n[parameters: (1229333908, 1, 0)]\n(Background on this error at: https://sqlalche.me/e/20/e3q8)'}
2025-08-22 17:21:01 | RepitBot | ERROR    | logger.py:228 | log_telegram_error | Telegram error: {'error_type': 'Global Error Handler', 'user_id': None, 'message': None, 'error': 'httpx.ConnectError: [Errno 11001] getaddrinfo failed'}
2025-08-22 17:21:02 | RepitBot | ERROR    | logger.py:228 | log_telegram_error | Telegram error: {'error_type': 'Global Error Handler', 'user_id': None, 'message': None, 'error': 'httpx.ConnectError: [Errno 11001] getaddrinfo failed'}
2025-08-22 17:21:03 | RepitBot | ERROR    | logger.py:228 | log_telegram_error | Telegram error: {'error_type': 'Global Error Handler', 'user_id': None, 'message': None, 'error': 'httpx.ConnectError: [Errno 11001] getaddrinfo failed'}
2025-08-22 17:21:05 | RepitBot | ERROR    | logger.py:228 | log_telegram_error | Telegram error: {'error_type': 'Global Error Handler', 'user_id': None, 'message': None, 'error': 'httpx.ConnectError: [Errno 11001] getaddrinfo failed'}
2025-08-22 17:24:16 | RepitBot | ERROR    | logger.py:228 | log_telegram_error | Telegram error: {'error_type': 'Global Error Handler', 'user_id': None, 'message': None, 'error': 'httpx.ConnectError: [Errno 11001] getaddrinfo failed'}
2025-08-22 17:24:21 | RepitBot | ERROR    | logger.py:228 | log_telegram_error | Telegram error: {'error_type': 'Global Error Handler', 'user_id': None, 'message': None, 'error': 'httpx.ConnectError: [Errno 11001] getaddrinfo failed'}
2025-08-22 17:26:34 | RepitBot | ERROR    | logger.py:228 | log_telegram_error | Telegram error: {'error_type': 'Global Error Handler', 'user_id': None, 'message': None, 'error': 'Conflict: terminated by other getUpdates request; make sure that only one bot instance is running'}
2025-08-22 17:26:38 | RepitBot | ERROR    | logger.py:228 | log_telegram_error | Telegram error: {'error_type': 'Global Error Handler', 'user_id': None, 'message': None, 'error': 'Conflict: terminated by other getUpdates request; make sure that only one bot instance is running'}
2025-08-22 17:26:40 | RepitBot | ERROR    | logger.py:228 | log_telegram_error | Telegram error: {'error_type': 'Global Error Handler', 'user_id': None, 'message': None, 'error': 'Conflict: terminated by other getUpdates request; make sure that only one bot instance is running'}
2025-08-22 17:26:44 | RepitBot | ERROR    | logger.py:228 | log_telegram_error | Telegram error: {'error_type': 'Global Error Handler', 'user_id': None, 'message': None, 'error': 'Conflict: terminated by other getUpdates request; make sure that only one bot instance is running'}
2025-08-22 17:26:46 | RepitBot | ERROR    | logger.py:228 | log_telegram_error | Telegram error: {'error_type': 'Global Error Handler', 'user_id': None, 'message': None, 'error': 'Conflict: terminated by other getUpdates request; make sure that only one bot instance is running'}
2025-08-22 17:28:47 | RepitBot | ERROR    | logger.py:228 | log_telegram_error | Telegram error: {'error_type': 'Global Error Handler', 'user_id': None, 'message': None, 'error': 'Conflict: terminated by other getUpdates request; make sure that only one bot instance is running'}
2025-08-22 17:28:51 | RepitBot | ERROR    | logger.py:228 | log_telegram_error | Telegram error: {'error_type': 'Global Error Handler', 'user_id': None, 'message': None, 'error': 'Conflict: terminated by other getUpdates request; make sure that only one bot instance is running'}
2025-08-22 17:28:52 | RepitBot | ERROR    | logger.py:228 | log_telegram_error | Telegram error: {'error_type': 'Global Error Handler', 'user_id': None, 'message': None, 'error': 'Conflict: terminated by other getUpdates request; make sure that only one bot instance is running'}
2025-08-22 17:28:56 | RepitBot | ERROR    | logger.py:228 | log_telegram_error | Telegram error: {'error_type': 'Global Error Handler', 'user_id': None, 'message': None, 'error': 'Conflict: terminated by other getUpdates request; make sure that only one bot instance is running'}
2025-08-22 17:28:58 | RepitBot | ERROR    | logger.py:228 | log_telegram_error | Telegram error: {'error_type': 'Global Error Handler', 'user_id': None, 'message': None, 'error': 'Conflict: terminated by other getUpdates request; make sure that only one bot instance is running'}
2025-08-22 17:29:03 | RepitBot | ERROR    | logger.py:228 | log_telegram_error | Telegram error: {'error_type': 'Global Error Handler', 'user_id': None, 'message': None, 'error': 'Conflict: terminated by other getUpdates request; make sure that only one bot instance is running'}
2025-08-22 17:29:39 | RepitBot | ERROR    | logger.py:228 | log_telegram_error | Telegram error: {'error_type': 'Global Error Handler', 'user_id': None, 'message': None, 'error': 'Conflict: terminated by other getUpdates request; make sure that only one bot instance is running'}
2025-08-22 17:29:43 | RepitBot | ERROR    | logger.py:228 | log_telegram_error | Telegram error: {'error_type': 'Global Error Handler', 'user_id': None, 'message': None, 'error': 'Conflict: terminated by other getUpdates request; make sure that only one bot instance is running'}
2025-08-22 17:29:44 | RepitBot | ERROR    | logger.py:228 | log_telegram_error | Telegram error: {'error_type': 'Global Error Handler', 'user_id': None, 'message': None, 'error': 'Conflict: terminated by other getUpdates request; make sure that only one bot instance is running'}
2025-08-22 17:29:46 | RepitBot | ERROR    | logger.py:228 | log_telegram_error | Telegram error: {'error_type': 'Global Error Handler', 'user_id': 1229333908, 'message': 'üéì –°–ø–∏—Å–æ–∫ —É—á–µ–Ω–∏–∫–æ–≤', 'error': '(sqlite3.OperationalError) no such column: users.grade\n[SQL: SELECT users.id AS users_id, users.telegram_id AS users_telegram_id, users.username AS users_username, users.full_name AS users_full_name, users.role AS users_role, users.access_code AS users_access_code, users.grade AS users_grade, users.points AS users_points, users.streak_days AS users_streak_days, users.last_lesson_date AS users_last_lesson_date, users.total_study_hours AS users_total_study_hours, users.created_at AS users_created_at, users.parent_id AS users_parent_id \nFROM users \nWHERE users.telegram_id = ?\n LIMIT ? OFFSET ?]\n[parameters: (1229333908, 1, 0)]\n(Background on this error at: https://sqlalche.me/e/20/e3q8)'}
2025-08-22 17:29:46 | RepitBot | ERROR    | logger.py:228 | log_telegram_error | Telegram error: {'error_type': 'Global Error Handler', 'user_id': 1229333908, 'message': 'üéì –°–ø–∏—Å–æ–∫ —É—á–µ–Ω–∏–∫–æ–≤', 'error': '(sqlite3.OperationalError) no such column: users.grade\n[SQL: SELECT users.id AS users_id, users.telegram_id AS users_telegram_id, users.username AS users_username, users.full_name AS users_full_name, users.role AS users_role, users.access_code AS users_access_code, users.grade AS users_grade, users.points AS users_points, users.streak_days AS users_streak_days, users.last_lesson_date AS users_last_lesson_date, users.total_study_hours AS users_total_study_hours, users.created_at AS users_created_at, users.parent_id AS users_parent_id \nFROM users \nWHERE users.telegram_id = ?\n LIMIT ? OFFSET ?]\n[parameters: (1229333908, 1, 0)]\n(Background on this error at: https://sqlalche.me/e/20/e3q8)'}
2025-08-22 17:29:49 | RepitBot | ERROR    | logger.py:228 | log_telegram_error | Telegram error: {'error_type': 'Global Error Handler', 'user_id': None, 'message': None, 'error': 'Conflict: terminated by other getUpdates request; make sure that only one bot instance is running'}
2025-08-22 17:29:50 | RepitBot | ERROR    | logger.py:228 | log_telegram_error | Telegram error: {'error_type': 'Global Error Handler', 'user_id': None, 'message': None, 'error': 'Conflict: terminated by other getUpdates request; make sure that only one bot instance is running'}
2025-08-22 17:29:54 | RepitBot | ERROR    | logger.py:228 | log_telegram_error | Telegram error: {'error_type': 'Global Error Handler', 'user_id': None, 'message': None, 'error': 'Conflict: terminated by other getUpdates request; make sure that only one bot instance is running'}
2025-08-22 17:29:56 | RepitBot | ERROR    | logger.py:228 | log_telegram_error | Telegram error: {'error_type': 'Global Error Handler', 'user_id': None, 'message': None, 'error': 'Conflict: terminated by other getUpdates request; make sure that only one bot instance is running'}
2025-08-22 17:30:01 | RepitBot | ERROR    | logger.py:228 | log_telegram_error | Telegram error: {'error_type': 'Global Error Handler', 'user_id': None, 'message': None, 'error': 'Conflict: terminated by other getUpdates request; make sure that only one bot instance is running'}
2025-08-22 17:30:03 | RepitBot | ERROR    | logger.py:228 | log_telegram_error | Telegram error: {'error_type': 'Global Error Handler', 'user_id': None, 'message': None, 'error': 'Conflict: terminated by other getUpdates request; make sure that only one bot instance is running'}
2025-08-22 17:30:08 | RepitBot | ERROR    | logger.py:228 | log_telegram_error | Telegram error: {'error_type': 'Global Error Handler', 'user_id': None, 'message': None, 'error': 'Conflict: terminated by other getUpdates request; make sure that only one bot instance is running'}
2025-08-22 17:30:12 | RepitBot | ERROR    | logger.py:228 | log_telegram_error | Telegram error: {'error_type': 'Global Error Handler', 'user_id': None, 'message': None, 'error': 'Conflict: terminated by other getUpdates request; make sure that only one bot instance is running'}
2025-08-22 17:30:16 | RepitBot | ERROR    | logger.py:228 | log_telegram_error | Telegram error: {'error_type': 'Global Error Handler', 'user_id': None, 'message': None, 'error': 'Conflict: terminated by other getUpdates request; make sure that only one bot instance is running'}
2025-08-22 17:30:29 | RepitBot.HealthMonitor | ERROR    | health_monitor.py:83 | run_check | Health check bot_connection timeout after 10s
2025-08-22 17:30:29 | RepitBot.HealthMonitor | CRITICAL | health_monitor.py:139 | _handle_critical_failure | üö® CRITICAL: Health check bot_connection failed 1 times
2025-08-22 17:30:53 | RepitBot | ERROR    | logger.py:228 | log_telegram_error | Telegram error: {'error_type': 'Global Error Handler', 'user_id': None, 'message': None, 'error': 'Conflict: terminated by other getUpdates request; make sure that only one bot instance is running'}
2025-08-22 17:30:57 | RepitBot | ERROR    | logger.py:228 | log_telegram_error | Telegram error: {'error_type': 'Global Error Handler', 'user_id': None, 'message': None, 'error': 'Conflict: terminated by other getUpdates request; make sure that only one bot instance is running'}
2025-08-22 17:30:59 | RepitBot | ERROR    | logger.py:228 | log_telegram_error | Telegram error: {'error_type': 'Global Error Handler', 'user_id': None, 'message': None, 'error': 'Conflict: terminated by other getUpdates request; make sure that only one bot instance is running'}
2025-08-22 17:31:04 | RepitBot | ERROR    | logger.py:228 | log_telegram_error | Telegram error: {'error_type': 'Global Error Handler', 'user_id': None, 'message': None, 'error': 'Conflict: terminated by other getUpdates request; make sure that only one bot instance is running'}
2025-08-22 17:31:36 | RepitBot | ERROR    | logger.py:228 | log_telegram_error | Telegram error: {'error_type': 'Global Error Handler', 'user_id': 1229333908, 'message': 'üéì –°–ø–∏—Å–æ–∫ —É—á–µ–Ω–∏–∫–æ–≤', 'error': '(sqlite3.OperationalError) no such column: users.grade\n[SQL: SELECT users.id AS users_id, users.telegram_id AS users_telegram_id, users.username AS users_username, users.full_name AS users_full_name, users.role AS users_role, users.access_code AS users_access_code, users.grade AS users_grade, users.points AS users_points, users.streak_days AS users_streak_days, users.last_lesson_date AS users_last_lesson_date, users.total_study_hours AS users_total_study_hours, users.created_at AS users_created_at, users.parent_id AS users_parent_id \nFROM users \nWHERE users.telegram_id = ?\n LIMIT ? OFFSET ?]\n[parameters: (1229333908, 1, 0)]\n(Background on this error at: https://sqlalche.me/e/20/e3q8)'}
2025-08-22 17:31:45 | RepitBot | ERROR    | logger.py:228 | log_telegram_error | Telegram error: {'error_type': 'Global Error Handler', 'user_id': 1229333908, 'message': 'üìä –û—Ç—á—ë—Ç –∑–∞ –º–µ—Å—è—Ü', 'error': '(sqlite3.OperationalError) no such column: users.grade\n[SQL: SELECT users.id AS users_id, users.telegram_id AS users_telegram_id, users.username AS users_username, users.full_name AS users_full_name, users.role AS users_role, users.access_code AS users_access_code, users.grade AS users_grade, users.points AS users_points, users.streak_days AS users_streak_days, users.last_lesson_date AS users_last_lesson_date, users.total_study_hours AS users_total_study_hours, users.created_at AS users_created_at, users.parent_id AS users_parent_id \nFROM users \nWHERE users.telegram_id = ?\n LIMIT ? OFFSET ?]\n[parameters: (1229333908, 1, 0)]\n(Background on this error at: https://sqlalche.me/e/20/e3q8)'}
2025-08-22 17:32:17 | RepitBot | ERROR    | logger.py:228 | log_telegram_error | Telegram error: {'error_type': 'Global Error Handler', 'user_id': 1229333908, 'message': 'üìä –û—Ç—á—ë—Ç –∑–∞ –º–µ—Å—è—Ü', 'error': '(sqlite3.OperationalError) no such column: users.grade\n[SQL: SELECT users.id AS users_id, users.telegram_id AS users_telegram_id, users.username AS users_username, users.full_name AS users_full_name, users.role AS users_role, users.access_code AS users_access_code, users.grade AS users_grade, users.points AS users_points, users.streak_days AS users_streak_days, users.last_lesson_date AS users_last_lesson_date, users.total_study_hours AS users_total_study_hours, users.created_at AS users_created_at, users.parent_id AS users_parent_id \nFROM users \nWHERE users.telegram_id = ?\n LIMIT ? OFFSET ?]\n[parameters: (1229333908, 1, 0)]\n(Background on this error at: https://sqlalche.me/e/20/e3q8)'}
2025-08-22 17:33:38 | RepitBot | ERROR    | logger.py:228 | log_telegram_error | Telegram error: {'error_type': 'Global Error Handler', 'user_id': 1229333908, 'message': 'üéì –°–ø–∏—Å–æ–∫ —É—á–µ–Ω–∏–∫–æ–≤', 'error': '(sqlite3.OperationalError) no such column: users.grade\n[SQL: SELECT users.id AS users_id, users.telegram_id AS users_telegram_id, users.username AS users_username, users.full_name AS users_full_name, users.role AS users_role, users.access_code AS users_access_code, users.grade AS users_grade, users.points AS users_points, users.streak_days AS users_streak_days, users.last_lesson_date AS users_last_lesson_date, users.total_study_hours AS users_total_study_hours, users.created_at AS users_created_at, users.parent_id AS users_parent_id \nFROM users \nWHERE users.telegram_id = ?\n LIMIT ? OFFSET ?]\n[parameters: (1229333908, 1, 0)]\n(Background on this error at: https://sqlalche.me/e/20/e3q8)'}
2025-08-22 17:35:39 | RepitBot | ERROR    | logger.py:228 | log_telegram_error | Telegram error: {'error_type': 'Global Error Handler', 'user_id': 1229333908, 'message': 'üéì –°–ø–∏—Å–æ–∫ —É—á–µ–Ω–∏–∫–æ–≤', 'error': '(sqlite3.OperationalError) no such column: users.grade\n[SQL: SELECT users.id AS users_id, users.telegram_id AS users_telegram_id, users.username AS users_username, users.full_name AS users_full_name, users.role AS users_role, users.access_code AS users_access_code, users.grade AS users_grade, users.points AS users_points, users.streak_days AS users_streak_days, users.last_lesson_date AS users_last_lesson_date, users.total_study_hours AS users_total_study_hours, users.created_at AS users_created_at, users.parent_id AS users_parent_id \nFROM users \nWHERE users.telegram_id = ?\n LIMIT ? OFFSET ?]\n[parameters: (1229333908, 1, 0)]\n(Background on this error at: https://sqlalche.me/e/20/e3q8)'}
2025-08-22 17:35:48 | RepitBot.HealthMonitor | ERROR    | health_monitor.py:83 | run_check | Health check bot_connection timeout after 10s
2025-08-22 17:35:49 | RepitBot.HealthMonitor | CRITICAL | health_monitor.py:139 | _handle_critical_failure | üö® CRITICAL: Health check bot_connection failed 1 times
2025-08-22 17:37:01 | RepitBot | ERROR    | logger.py:228 | log_telegram_error | Telegram error: {'error_type': 'Global Error Handler', 'user_id': 1229333908, 'message': 'üéì –°–ø–∏—Å–æ–∫ —É—á–µ–Ω–∏–∫–æ–≤', 'error': '(sqlite3.OperationalError) no such column: users.grade\n[SQL: SELECT users.id AS users_id, users.telegram_id AS users_telegram_id, users.username AS users_username, users.full_name AS users_full_name, users.role AS users_role, users.access_code AS users_access_code, users.grade AS users_grade, users.points AS users_points, users.streak_days AS users_streak_days, users.last_lesson_date AS users_last_lesson_date, users.total_study_hours AS users_total_study_hours, users.created_at AS users_created_at, users.parent_id AS users_parent_id \nFROM users \nWHERE users.telegram_id = ?\n LIMIT ? OFFSET ?]\n[parameters: (1229333908, 1, 0)]\n(Background on this error at: https://sqlalche.me/e/20/e3q8)'}
2025-08-22 17:37:19 | RepitBot | ERROR    | logger.py:228 | log_telegram_error | Telegram error: {'error_type': 'Global Error Handler', 'user_id': 1229333908, 'message': 'MARINA2024', 'error': '(sqlite3.OperationalError) no such column: users.grade\n[SQL: SELECT users.id AS users_id, users.telegram_id AS users_telegram_id, users.username AS users_username, users.full_name AS users_full_name, users.role AS users_role, users.access_code AS users_access_code, users.grade AS users_grade, users.points AS users_points, users.streak_days AS users_streak_days, users.last_lesson_date AS users_last_lesson_date, users.total_study_hours AS users_total_study_hours, users.created_at AS users_created_at, users.parent_id AS users_parent_id \nFROM users \nWHERE users.telegram_id = ?\n LIMIT ? OFFSET ?]\n[parameters: (1229333908, 1, 0)]\n(Background on this error at: https://sqlalche.me/e/20/e3q8)'}
2025-08-22 18:17:21 | RepitBot | ERROR    | logger.py:228 | log_telegram_error | Telegram error: {'error_type': 'Global Error Handler', 'user_id': None, 'message': None, 'error': 'httpx.RemoteProtocolError: Server disconnected without sending a response.'}
2025-08-22 18:17:22 | RepitBot | ERROR    | logger.py:228 | log_telegram_error | Telegram error: {'error_type': 'Global Error Handler', 'user_id': None, 'message': None, 'error': 'httpx.ConnectError: [Errno 11001] getaddrinfo failed'}
2025-08-22 18:17:24 | RepitBot | ERROR    | logger.py:228 | log_telegram_error | Telegram error: {'error_type': 'Global Error Handler', 'user_id': None, 'message': None, 'error': 'httpx.ConnectError: [Errno 11001] getaddrinfo failed'}
2025-08-22 18:17:26 | RepitBot | ERROR    | logger.py:228 | log_telegram_error | Telegram error: {'error_type': 'Global Error Handler', 'user_id': None, 'message': None, 'error': 'httpx.ConnectError: [Errno 11001] getaddrinfo failed'}
2025-08-22 18:17:30 | RepitBot | ERROR    | logger.py:228 | log_telegram_error | Telegram error: {'error_type': 'Global Error Handler', 'user_id': None, 'message': None, 'error': 'httpx.ConnectError: [Errno 11001] getaddrinfo failed'}
2025-08-22 18:17:35 | RepitBot | ERROR    | logger.py:228 | log_telegram_error | Telegram error: {'error_type': 'Global Error Handler', 'user_id': None, 'message': None, 'error': 'httpx.ConnectError: [Errno 11001] getaddrinfo failed'}
2025-08-22 18:17:42 | RepitBot | ERROR    | logger.py:228 | log_telegram_error | Telegram error: {'error_type': 'Global Error Handler', 'user_id': None, 'message': None, 'error': 'httpx.ConnectError: [Errno 11001] getaddrinfo failed'}
2025-08-22 18:17:54 | RepitBot | ERROR    | logger.py:228 | log_telegram_error | Telegram error: {'error_type': 'Global Error Handler', 'user_id': None, 'message': None, 'error': 'httpx.ConnectError: [Errno 11001] getaddrinfo failed'}
2025-08-22 18:18:11 | RepitBot | ERROR    | logger.py:228 | log_telegram_error | Telegram error: {'error_type': 'Global Error Handler', 'user_id': None, 'message': None, 'error': 'httpx.ConnectError: [Errno 11001] getaddrinfo failed'}
2025-08-22 18:18:48 | RepitBot | ERROR    | logger.py:228 | log_telegram_error | Telegram error: {'error_type': 'Global Error Handler', 'user_id': None, 'message': None, 'error': 'httpx.ConnectError: [Errno 11001] getaddrinfo failed'}
2025-08-22 18:18:59 | RepitBot.HealthMonitor | ERROR    | health_monitor.py:83 | run_check | Health check bot_connection timeout after 10s
2025-08-22 18:18:59 | RepitBot.HealthMonitor | CRITICAL | health_monitor.py:139 | _handle_critical_failure | üö® CRITICAL: Health check bot_connection failed 1 times
2025-08-22 18:19:05 | RepitBot | ERROR    | logger.py:228 | log_telegram_error | Telegram error: {'error_type': 'Global Error Handler', 'user_id': None, 'message': None, 'error': 'httpx.ConnectError: [Errno 11001] getaddrinfo failed'}
2025-08-22 18:19:06 | RepitBot | ERROR    | logger.py:228 | log_telegram_error | Telegram error: {'error_type': 'Global Error Handler', 'user_id': None, 'message': None, 'error': 'httpx.ConnectError: [Errno 11001] getaddrinfo failed'}
2025-08-22 18:19:07 | RepitBot.HealthMonitor | ERROR    | health_monitor.py:174 | _recover_bot_connection | ‚ùå Failed to recover bot connection: httpx.ConnectError: [Errno 11001] getaddrinfo failed
2025-08-22 18:19:07 | RepitBot | ERROR    | logger.py:228 | log_telegram_error | Telegram error: {'error_type': 'Global Error Handler', 'user_id': None, 'message': None, 'error': 'httpx.ConnectError: [Errno 11001] getaddrinfo failed'}
2025-08-22 18:19:09 | RepitBot | ERROR    | logger.py:228 | log_telegram_error | Telegram error: {'error_type': 'Global Error Handler', 'user_id': None, 'message': None, 'error': 'httpx.ConnectError: [Errno 11001] getaddrinfo failed'}
2025-08-22 18:19:13 | RepitBot | ERROR    | logger.py:228 | log_telegram_error | Telegram error: {'error_type': 'Global Error Handler', 'user_id': None, 'message': None, 'error': 'httpx.ConnectError: [Errno 11001] getaddrinfo failed'}
2025-08-22 18:19:30 | RepitBot | ERROR    | logger.py:228 | log_telegram_error | Telegram error: {'error_type': 'Global Error Handler', 'user_id': None, 'message': None, 'error': 'httpx.ConnectError: [Errno 11001] getaddrinfo failed'}
2025-08-22 18:19:41 | RepitBot | ERROR    | logger.py:228 | log_telegram_error | Telegram error: {'error_type': 'Global Error Handler', 'user_id': None, 'message': None, 'error': 'httpx.ConnectError: [Errno 11001] getaddrinfo failed'}
2025-08-22 18:19:42 | RepitBot | ERROR    | logger.py:228 | log_telegram_error | Telegram error: {'error_type': 'Global Error Handler', 'user_id': None, 'message': None, 'error': 'httpx.ConnectError: [Errno 11001] getaddrinfo failed'}
2025-08-22 18:19:43 | RepitBot | ERROR    | logger.py:228 | log_telegram_error | Telegram error: {'error_type': 'Global Error Handler', 'user_id': None, 'message': None, 'error': 'httpx.ConnectError: [Errno 11001] getaddrinfo failed'}
2025-08-22 18:19:46 | RepitBot | ERROR    | logger.py:228 | log_telegram_error | Telegram error: {'error_type': 'Global Error Handler', 'user_id': None, 'message': None, 'error': 'httpx.ConnectError: [Errno 11001] getaddrinfo failed'}
2025-08-22 18:19:49 | RepitBot | ERROR    | logger.py:228 | log_telegram_error | Telegram error: {'error_type': 'Global Error Handler', 'user_id': None, 'message': None, 'error': 'httpx.ConnectError: [Errno 11001] getaddrinfo failed'}
2025-08-22 18:19:54 | RepitBot | ERROR    | logger.py:228 | log_telegram_error | Telegram error: {'error_type': 'Global Error Handler', 'user_id': None, 'message': None, 'error': 'httpx.ConnectError: [Errno 11001] getaddrinfo failed'}
2025-08-22 18:20:07 | RepitBot | ERROR    | logger.py:228 | log_telegram_error | Telegram error: {'error_type': 'Global Error Handler', 'user_id': None, 'message': None, 'error': 'httpx.ConnectError: [Errno 11001] getaddrinfo failed'}
2025-08-22 18:20:08 | RepitBot | ERROR    | logger.py:228 | log_telegram_error | Telegram error: {'error_type': 'Global Error Handler', 'user_id': None, 'message': None, 'error': 'httpx.ConnectError: [Errno 11001] getaddrinfo failed'}
2025-08-22 18:20:09 | RepitBot | ERROR    | logger.py:228 | log_telegram_error | Telegram error: {'error_type': 'Global Error Handler', 'user_id': None, 'message': None, 'error': 'httpx.ConnectError: [Errno 11001] getaddrinfo failed'}
2025-08-22 18:20:11 | RepitBot | ERROR    | logger.py:228 | log_telegram_error | Telegram error: {'error_type': 'Global Error Handler', 'user_id': None, 'message': None, 'error': 'httpx.ConnectError: [Errno 11001] getaddrinfo failed'}
2025-08-22 18:20:15 | RepitBot | ERROR    | logger.py:228 | log_telegram_error | Telegram error: {'error_type': 'Global Error Handler', 'user_id': None, 'message': None, 'error': 'httpx.ConnectError: [Errno 11001] getaddrinfo failed'}
2025-08-22 18:20:20 | RepitBot | ERROR    | logger.py:228 | log_telegram_error | Telegram error: {'error_type': 'Global Error Handler', 'user_id': None, 'message': None, 'error': 'httpx.ConnectError: [Errno 11001] getaddrinfo failed'}
2025-08-22 18:20:28 | RepitBot | ERROR    | logger.py:228 | log_telegram_error | Telegram error: {'error_type': 'Global Error Handler', 'user_id': None, 'message': None, 'error': 'httpx.ConnectError: [Errno 11001] getaddrinfo failed'}
2025-08-22 18:20:39 | RepitBot | ERROR    | logger.py:228 | log_telegram_error | Telegram error: {'error_type': 'Global Error Handler', 'user_id': None, 'message': None, 'error': 'httpx.ConnectError: [Errno 11001] getaddrinfo failed'}
2025-08-22 18:20:56 | RepitBot | ERROR    | logger.py:228 | log_telegram_error | Telegram error: {'error_type': 'Global Error Handler', 'user_id': None, 'message': None, 'error': 'httpx.ConnectError: [Errno 11001] getaddrinfo failed'}
2025-08-22 18:21:22 | RepitBot | ERROR    | logger.py:228 | log_telegram_error | Telegram error: {'error_type': 'Global Error Handler', 'user_id': None, 'message': None, 'error': 'httpx.ConnectError: [Errno 11001] getaddrinfo failed'}
2025-08-22 18:22:00 | RepitBot | ERROR    | bot.py:413 | main | –ö—Ä–∏—Ç–∏—á–µ—Å–∫–∞—è –æ—à–∏–±–∫–∞ –ø—Ä–∏ –∑–∞–ø—É—Å–∫–µ –±–æ—Ç–∞: httpx.ConnectError: [Errno 11001] getaddrinfo failed
2025-08-22 18:25:01 | RepitBot | ERROR    | logger.py:228 | log_telegram_error | Telegram error: {'error_type': 'Global Error Handler', 'user_id': 1229333908, 'message': 'Callback: parent_select_existing', 'error': "Parent instance <User at 0x16a2be734d0> is not bound to a Session; lazy load operation of attribute 'children' cannot proceed (Background on this error at: https://sqlalche.me/e/20/bhk3)"}
2025-08-22 18:32:40 | RepitBot.HealthMonitor | ERROR    | health_monitor.py:83 | run_check | Health check bot_connection timeout after 10s
2025-08-22 18:32:40 | RepitBot.HealthMonitor | CRITICAL | health_monitor.py:139 | _handle_critical_failure | üö® CRITICAL: Health check bot_connection failed 1 times
2025-08-22 18:33:51 | RepitBot | ERROR    | logger.py:228 | log_telegram_error | Telegram error: {'error_type': 'Global Error Handler', 'user_id': 1229333908, 'message': 'üéì –°–ø–∏—Å–æ–∫ —É—á–µ–Ω–∏–∫–æ–≤', 'error': 'httpx.ConnectError: [Errno 11001] getaddrinfo failed'}
2025-08-22 18:34:19 | RepitBot | ERROR    | logger.py:228 | log_telegram_error | Telegram error: {'error_type': 'Global Error Handler', 'user_id': 1229333908, 'message': 'Callback: parent_select_16', 'error': 'Instance <User at 0x20027794bd0> is not bound to a Session; attribute refresh operation cannot proceed (Background on this error at: https://sqlalche.me/e/20/bhk3)'}
2025-08-22 18:45:32 | RepitBot | ERROR    | logger.py:228 | log_telegram_error | Telegram error: {'error_type': 'Global Error Handler', 'user_id': None, 'message': None, 'error': 'Conflict: terminated by other getUpdates request; make sure that only one bot instance is running'}
2025-08-22 18:45:37 | RepitBot | ERROR    | logger.py:228 | log_telegram_error | Telegram error: {'error_type': 'Global Error Handler', 'user_id': None, 'message': None, 'error': 'Conflict: terminated by other getUpdates request; make sure that only one bot instance is running'}
2025-08-22 18:45:38 | RepitBot | ERROR    | logger.py:228 | log_telegram_error | Telegram error: {'error_type': 'Global Error Handler', 'user_id': None, 'message': None, 'error': 'Conflict: terminated by other getUpdates request; make sure that only one bot instance is running'}
2025-08-22 18:45:43 | RepitBot | ERROR    | logger.py:228 | log_telegram_error | Telegram error: {'error_type': 'Global Error Handler', 'user_id': None, 'message': None, 'error': 'Conflict: terminated by other getUpdates request; make sure that only one bot instance is running'}
2025-08-22 18:45:44 | RepitBot | ERROR    | logger.py:228 | log_telegram_error | Telegram error: {'error_type': 'Global Error Handler', 'user_id': None, 'message': None, 'error': 'Conflict: terminated by other getUpdates request; make sure that only one bot instance is running'}
2025-08-22 18:45:50 | RepitBot | ERROR    | logger.py:228 | log_telegram_error | Telegram error: {'error_type': 'Global Error Handler', 'user_id': None, 'message': None, 'error': 'Conflict: terminated by other getUpdates request; make sure that only one bot instance is running'}
2025-08-22 18:45:52 | RepitBot | ERROR    | logger.py:228 | log_telegram_error | Telegram error: {'error_type': 'Global Error Handler', 'user_id': None, 'message': None, 'error': 'Conflict: terminated by other getUpdates request; make sure that only one bot instance is running'}
2025-08-22 18:45:56 | RepitBot | ERROR    | logger.py:228 | log_telegram_error | Telegram error: {'error_type': 'Global Error Handler', 'user_id': None, 'message': None, 'error': 'Conflict: terminated by other getUpdates request; make sure that only one bot instance is running'}
2025-08-22 18:45:59 | RepitBot | ERROR    | logger.py:228 | log_telegram_error | Telegram error: {'error_type': 'Global Error Handler', 'user_id': None, 'message': None, 'error': 'Conflict: terminated by other getUpdates request; make sure that only one bot instance is running'}
2025-08-22 18:46:05 | RepitBot | ERROR    | logger.py:228 | log_telegram_error | Telegram error: {'error_type': 'Global Error Handler', 'user_id': None, 'message': None, 'error': 'Conflict: terminated by other getUpdates request; make sure that only one bot instance is running'}
2025-08-22 18:46:10 | RepitBot | ERROR    | logger.py:228 | log_telegram_error | Telegram error: {'error_type': 'Global Error Handler', 'user_id': None, 'message': None, 'error': 'Conflict: terminated by other getUpdates request; make sure that only one bot instance is running'}
2025-08-22 18:46:18 | RepitBot | ERROR    | logger.py:228 | log_telegram_error | Telegram error: {'error_type': 'Global Error Handler', 'user_id': None, 'message': None, 'error': 'Conflict: terminated by other getUpdates request; make sure that only one bot instance is running'}
2025-08-22 18:46:27 | RepitBot | ERROR    | logger.py:228 | log_telegram_error | Telegram error: {'error_type': 'Global Error Handler', 'user_id': None, 'message': None, 'error': 'Conflict: terminated by other getUpdates request; make sure that only one bot instance is running'}
2025-08-22 18:46:38 | RepitBot | ERROR    | logger.py:228 | log_telegram_error | Telegram error: {'error_type': 'Global Error Handler', 'user_id': None, 'message': None, 'error': 'Conflict: terminated by other getUpdates request; make sure that only one bot instance is running'}
2025-08-22 18:46:50 | RepitBot | ERROR    | logger.py:228 | log_telegram_error | Telegram error: {'error_type': 'Global Error Handler', 'user_id': None, 'message': None, 'error': 'Conflict: terminated by other getUpdates request; make sure that only one bot instance is running'}
2025-08-22 18:47:08 | RepitBot | ERROR    | logger.py:228 | log_telegram_error | Telegram error: {'error_type': 'Global Error Handler', 'user_id': None, 'message': None, 'error': 'Conflict: terminated by other getUpdates request; make sure that only one bot instance is running'}
2025-08-22 18:47:26 | RepitBot | ERROR    | logger.py:228 | log_telegram_error | Telegram error: {'error_type': 'Global Error Handler', 'user_id': None, 'message': None, 'error': 'Conflict: terminated by other getUpdates request; make sure that only one bot instance is running'}
2025-08-22 18:47:52 | RepitBot | ERROR    | logger.py:228 | log_telegram_error | Telegram error: {'error_type': 'Global Error Handler', 'user_id': None, 'message': None, 'error': 'Conflict: terminated by other getUpdates request; make sure that only one bot instance is running'}
2025-08-22 18:48:18 | RepitBot | ERROR    | logger.py:228 | log_telegram_error | Telegram error: {'error_type': 'Global Error Handler', 'user_id': None, 'message': None, 'error': 'Conflict: terminated by other getUpdates request; make sure that only one bot instance is running'}
2025-08-22 18:48:49 | RepitBot | ERROR    | logger.py:228 | log_telegram_error | Telegram error: {'error_type': 'Global Error Handler', 'user_id': None, 'message': None, 'error': 'Conflict: terminated by other getUpdates request; make sure that only one bot instance is running'}
2025-08-22 18:48:53 | RepitBot | ERROR    | logger.py:228 | log_telegram_error | Telegram error: {'error_type': 'Global Error Handler', 'user_id': None, 'message': None, 'error': 'Conflict: terminated by other getUpdates request; make sure that only one bot instance is running'}
2025-08-22 18:49:24 | RepitBot | ERROR    | logger.py:228 | log_telegram_error | Telegram error: {'error_type': 'Global Error Handler', 'user_id': None, 'message': None, 'error': 'Conflict: terminated by other getUpdates request; make sure that only one bot instance is running'}
2025-08-22 18:49:28 | RepitBot | ERROR    | logger.py:228 | log_telegram_error | Telegram error: {'error_type': 'Global Error Handler', 'user_id': None, 'message': None, 'error': 'Conflict: terminated by other getUpdates request; make sure that only one bot instance is running'}
2025-08-22 18:49:43 | RepitBot.HealthMonitor | ERROR    | health_monitor.py:83 | run_check | Health check bot_connection timeout after 10s
2025-08-22 18:49:43 | RepitBot.HealthMonitor | CRITICAL | health_monitor.py:139 | _handle_critical_failure | üö® CRITICAL: Health check bot_connection failed 1 times
2025-08-22 18:50:00 | RepitBot | ERROR    | logger.py:228 | log_telegram_error | Telegram error: {'error_type': 'Global Error Handler', 'user_id': None, 'message': None, 'error': 'Conflict: terminated by other getUpdates request; make sure that only one bot instance is running'}
2025-08-22 18:50:05 | RepitBot | ERROR    | logger.py:228 | log_telegram_error | Telegram error: {'error_type': 'Global Error Handler', 'user_id': None, 'message': None, 'error': 'Conflict: terminated by other getUpdates request; make sure that only one bot instance is running'}
2025-08-22 18:50:35 | RepitBot | ERROR    | logger.py:228 | log_telegram_error | Telegram error: {'error_type': 'Global Error Handler', 'user_id': None, 'message': None, 'error': 'Conflict: terminated by other getUpdates request; make sure that only one bot instance is running'}
2025-08-22 18:50:39 | RepitBot | ERROR    | logger.py:228 | log_telegram_error | Telegram error: {'error_type': 'Global Error Handler', 'user_id': None, 'message': None, 'error': 'Conflict: terminated by other getUpdates request; make sure that only one bot instance is running'}
2025-08-22 18:51:10 | RepitBot | ERROR    | logger.py:228 | log_telegram_error | Telegram error: {'error_type': 'Global Error Handler', 'user_id': None, 'message': None, 'error': 'Conflict: terminated by other getUpdates request; make sure that only one bot instance is running'}
2025-08-22 18:51:14 | RepitBot | ERROR    | logger.py:228 | log_telegram_error | Telegram error: {'error_type': 'Global Error Handler', 'user_id': None, 'message': None, 'error': 'Conflict: terminated by other getUpdates request; make sure that only one bot instance is running'}
2025-08-22 18:51:45 | RepitBot | ERROR    | logger.py:228 | log_telegram_error | Telegram error: {'error_type': 'Global Error Handler', 'user_id': None, 'message': None, 'error': 'Conflict: terminated by other getUpdates request; make sure that only one bot instance is running'}
2025-08-22 18:51:49 | RepitBot | ERROR    | logger.py:228 | log_telegram_error | Telegram error: {'error_type': 'Global Error Handler', 'user_id': None, 'message': None, 'error': 'Conflict: terminated by other getUpdates request; make sure that only one bot instance is running'}
2025-08-22 18:52:19 | RepitBot | ERROR    | logger.py:228 | log_telegram_error | Telegram error: {'error_type': 'Global Error Handler', 'user_id': None, 'message': None, 'error': 'Conflict: terminated by other getUpdates request; make sure that only one bot instance is running'}
2025-08-22 18:52:23 | RepitBot | ERROR    | logger.py:228 | log_telegram_error | Telegram error: {'error_type': 'Global Error Handler', 'user_id': None, 'message': None, 'error': 'Conflict: terminated by other getUpdates request; make sure that only one bot instance is running'}
2025-08-22 18:52:54 | RepitBot | ERROR    | logger.py:228 | log_telegram_error | Telegram error: {'error_type': 'Global Error Handler', 'user_id': None, 'message': None, 'error': 'Conflict: terminated by other getUpdates request; make sure that only one bot instance is running'}
2025-08-22 18:52:58 | RepitBot | ERROR    | logger.py:228 | log_telegram_error | Telegram error: {'error_type': 'Global Error Handler', 'user_id': None, 'message': None, 'error': 'Conflict: terminated by other getUpdates request; make sure that only one bot instance is running'}
2025-08-22 18:53:29 | RepitBot | ERROR    | logger.py:228 | log_telegram_error | Telegram error: {'error_type': 'Global Error Handler', 'user_id': None, 'message': None, 'error': 'Conflict: terminated by other getUpdates request; make sure that only one bot instance is running'}
2025-08-22 18:53:33 | RepitBot | ERROR    | logger.py:228 | log_telegram_error | Telegram error: {'error_type': 'Global Error Handler', 'user_id': None, 'message': None, 'error': 'Conflict: terminated by other getUpdates request; make sure that only one bot instance is running'}
2025-08-22 18:54:03 | RepitBot | ERROR    | logger.py:228 | log_telegram_error | Telegram error: {'error_type': 'Global Error Handler', 'user_id': None, 'message': None, 'error': 'Conflict: terminated by other getUpdates request; make sure that only one bot instance is running'}
2025-08-22 18:54:08 | RepitBot | ERROR    | logger.py:228 | log_telegram_error | Telegram error: {'error_type': 'Global Error Handler', 'user_id': None, 'message': None, 'error': 'Conflict: terminated by other getUpdates request; make sure that only one bot instance is running'}
2025-08-22 18:54:38 | RepitBot | ERROR    | logger.py:228 | log_telegram_error | Telegram error: {'error_type': 'Global Error Handler', 'user_id': None, 'message': None, 'error': 'Conflict: terminated by other getUpdates request; make sure that only one bot instance is running'}
2025-08-22 18:54:42 | RepitBot | ERROR    | logger.py:228 | log_telegram_error | Telegram error: {'error_type': 'Global Error Handler', 'user_id': None, 'message': None, 'error': 'Conflict: terminated by other getUpdates request; make sure that only one bot instance is running'}
2025-08-22 18:55:13 | RepitBot | ERROR    | logger.py:228 | log_telegram_error | Telegram error: {'error_type': 'Global Error Handler', 'user_id': None, 'message': None, 'error': 'Conflict: terminated by other getUpdates request; make sure that only one bot instance is running'}
2025-08-22 18:55:17 | RepitBot | ERROR    | logger.py:228 | log_telegram_error | Telegram error: {'error_type': 'Global Error Handler', 'user_id': None, 'message': None, 'error': 'Conflict: terminated by other getUpdates request; make sure that only one bot instance is running'}
2025-08-22 18:55:48 | RepitBot | ERROR    | logger.py:228 | log_telegram_error | Telegram error: {'error_type': 'Global Error Handler', 'user_id': None, 'message': None, 'error': 'Conflict: terminated by other getUpdates request; make sure that only one bot instance is running'}
2025-08-22 18:55:52 | RepitBot | ERROR    | logger.py:228 | log_telegram_error | Telegram error: {'error_type': 'Global Error Handler', 'user_id': None, 'message': None, 'error': 'Conflict: terminated by other getUpdates request; make sure that only one bot instance is running'}
2025-08-22 18:56:23 | RepitBot | ERROR    | logger.py:228 | log_telegram_error | Telegram error: {'error_type': 'Global Error Handler', 'user_id': None, 'message': None, 'error': 'Conflict: terminated by other getUpdates request; make sure that only one bot instance is running'}
2025-08-22 18:56:27 | RepitBot | ERROR    | logger.py:228 | log_telegram_error | Telegram error: {'error_type': 'Global Error Handler', 'user_id': None, 'message': None, 'error': 'Conflict: terminated by other getUpdates request; make sure that only one bot instance is running'}
2025-08-22 18:56:57 | RepitBot | ERROR    | logger.py:228 | log_telegram_error | Telegram error: {'error_type': 'Global Error Handler', 'user_id': None, 'message': None, 'error': 'Conflict: terminated by other getUpdates request; make sure that only one bot instance is running'}
2025-08-22 18:57:01 | RepitBot | ERROR    | logger.py:228 | log_telegram_error | Telegram error: {'error_type': 'Global Error Handler', 'user_id': None, 'message': None, 'error': 'Conflict: terminated by other getUpdates request; make sure that only one bot instance is running'}
2025-08-22 18:57:32 | RepitBot | ERROR    | logger.py:228 | log_telegram_error | Telegram error: {'error_type': 'Global Error Handler', 'user_id': None, 'message': None, 'error': 'Conflict: terminated by other getUpdates request; make sure that only one bot instance is running'}
2025-08-22 18:57:36 | RepitBot | ERROR    | logger.py:228 | log_telegram_error | Telegram error: {'error_type': 'Global Error Handler', 'user_id': None, 'message': None, 'error': 'Conflict: terminated by other getUpdates request; make sure that only one bot instance is running'}
2025-08-22 21:37:02 | RepitBot | ERROR    | logger.py:228 | log_telegram_error | Telegram error: {'error_type': 'Global Error Handler', 'user_id': 1229333908, 'message': 'Callback: tutor_set_attendance_77_excused_absence', 'error': 'Message is not modified: specified new message content and reply markup are exactly the same as a current content and reply markup of the message'}
2025-08-22 21:40:47 | RepitBot | ERROR    | logger.py:228 | log_telegram_error | Telegram error: {'error_type': 'Global Error Handler', 'user_id': 1229333908, 'message': 'Callback: tutor_set_attendance_79_excused_absence', 'error': 'Message is not modified: specified new message content and reply markup are exactly the same as a current content and reply markup of the message'}
2025-08-22 21:50:09 | RepitBot | ERROR    | logger.py:228 | log_telegram_error | Telegram error: {'error_type': 'Global Error Handler', 'user_id': None, 'message': None, 'error': 'httpx.RemoteProtocolError: Server disconnected without sending a response.'}
2025-08-22 21:50:10 | RepitBot | ERROR    | logger.py:228 | log_telegram_error | Telegram error: {'error_type': 'Global Error Handler', 'user_id': None, 'message': None, 'error': 'httpx.ConnectError: '}
2025-08-22 21:50:12 | RepitBot | ERROR    | logger.py:228 | log_telegram_error | Telegram error: {'error_type': 'Global Error Handler', 'user_id': None, 'message': None, 'error': 'httpx.ConnectError: '}
2025-08-22 21:50:15 | RepitBot | ERROR    | logger.py:228 | log_telegram_error | Telegram error: {'error_type': 'Global Error Handler', 'user_id': None, 'message': None, 'error': 'httpx.ConnectError: '}
2025-08-22 21:50:18 | RepitBot | ERROR    | logger.py:228 | log_telegram_error | Telegram error: {'error_type': 'Global Error Handler', 'user_id': None, 'message': None, 'error': 'httpx.ConnectError: '}
2025-08-22 21:50:35 | RepitBot | ERROR    | logger.py:228 | log_telegram_error | Telegram error: {'error_type': 'Global Error Handler', 'user_id': None, 'message': None, 'error': 'httpx.ConnectError: '}
2025-08-22 21:50:39 | RepitBot | ERROR    | logger.py:228 | log_telegram_error | Telegram error: {'error_type': 'Global Error Handler', 'user_id': None, 'message': None, 'error': 'httpx.ConnectError: '}
2025-08-22 22:20:16 | RepitBot.HealthMonitor | ERROR    | health_monitor.py:83 | run_check | Health check bot_connection timeout after 10s
2025-08-22 22:20:16 | RepitBot.HealthMonitor | CRITICAL | health_monitor.py:139 | _handle_critical_failure | üö® CRITICAL: Health check bot_connection failed 1 times
2025-08-22 23:19:10 | RepitBot.HealthMonitor | ERROR    | health_monitor.py:83 | run_check | Health check bot_connection timeout after 10s
2025-08-22 23:19:10 | RepitBot.HealthMonitor | CRITICAL | health_monitor.py:139 | _handle_critical_failure | üö® CRITICAL: Health check bot_connection failed 1 times
2025-08-22 23:19:12 | RepitBot | ERROR    | logger.py:228 | log_telegram_error | Telegram error: {'error_type': 'Global Error Handler', 'user_id': None, 'message': None, 'error': 'httpx.ConnectError: [Errno 11001] getaddrinfo failed'}
2025-08-22 23:19:12 | RepitBot.HealthMonitor | ERROR    | health_monitor.py:174 | _recover_bot_connection | ‚ùå Failed to recover bot connection: httpx.ConnectError: [Errno 11001] getaddrinfo failed
2025-08-22 23:19:28 | RepitBot | ERROR    | logger.py:228 | log_telegram_error | Telegram error: {'error_type': 'Global Error Handler', 'user_id': None, 'message': None, 'error': 'httpx.ConnectError: [Errno 11001] getaddrinfo failed'}
2025-08-22 23:19:30 | RepitBot | ERROR    | logger.py:228 | log_telegram_error | Telegram error: {'error_type': 'Global Error Handler', 'user_id': None, 'message': None, 'error': 'httpx.ConnectError: [Errno 11001] getaddrinfo failed'}
2025-08-22 23:19:32 | RepitBot | ERROR    | logger.py:228 | log_telegram_error | Telegram error: {'error_type': 'Global Error Handler', 'user_id': None, 'message': None, 'error': 'httpx.ConnectError: [Errno 11001] getaddrinfo failed'}
2025-08-22 23:19:35 | RepitBot | ERROR    | logger.py:228 | log_telegram_error | Telegram error: {'error_type': 'Global Error Handler', 'user_id': None, 'message': None, 'error': 'httpx.ConnectError: [Errno 11001] getaddrinfo failed'}
2025-08-22 23:19:38 | RepitBot | ERROR    | logger.py:228 | log_telegram_error | Telegram error: {'error_type': 'Global Error Handler', 'user_id': None, 'message': None, 'error': 'httpx.ConnectError: [Errno 11001] getaddrinfo failed'}
2025-08-22 23:19:46 | RepitBot | ERROR    | logger.py:228 | log_telegram_error | Telegram error: {'error_type': 'Global Error Handler', 'user_id': None, 'message': None, 'error': 'httpx.ReadError: '}
2025-08-22 23:20:11 | RepitBot | ERROR    | logger.py:228 | log_telegram_error | Telegram error: {'error_type': 'Global Error Handler', 'user_id': None, 'message': None, 'error': 'httpx.ConnectError: [Errno 11001] getaddrinfo failed'}
2025-08-22 23:20:24 | RepitBot | ERROR    | logger.py:228 | log_telegram_error | Telegram error: {'error_type': 'Global Error Handler', 'user_id': None, 'message': None, 'error': 'httpx.ConnectError: [Errno 11001] getaddrinfo failed'}
2025-08-22 23:27:16 | RepitBot.HealthMonitor | ERROR    | health_monitor.py:83 | run_check | Health check bot_connection timeout after 10s
2025-08-22 23:27:16 | RepitBot.HealthMonitor | CRITICAL | health_monitor.py:139 | _handle_critical_failure | üö® CRITICAL: Health check bot_connection failed 1 times
2025-08-22 23:27:18 | RepitBot.HealthMonitor | ERROR    | health_monitor.py:174 | _recover_bot_connection | ‚ùå Failed to recover bot connection: httpx.ConnectError: [Errno 11001] getaddrinfo failed
2025-08-22 23:29:19 | RepitBot.HealthMonitor | ERROR    | health_monitor.py:83 | run_check | Health check bot_connection timeout after 10s
2025-08-22 23:29:19 | RepitBot.HealthMonitor | CRITICAL | health_monitor.py:139 | _handle_critical_failure | üö® CRITICAL: Health check bot_connection failed 2 times
2025-08-22 23:29:21 | RepitBot.HealthMonitor | ERROR    | health_monitor.py:174 | _recover_bot_connection | ‚ùå Failed to recover bot connection: httpx.ConnectError: [Errno 11001] getaddrinfo failed
2025-08-23 00:03:50 | RepitBot.HealthMonitor | ERROR    | health_monitor.py:83 | run_check | Health check bot_connection timeout after 10s
2025-08-23 00:03:51 | RepitBot.HealthMonitor | CRITICAL | health_monitor.py:139 | _handle_critical_failure | üö® CRITICAL: Health check bot_connection failed 1 times
2025-08-23 00:08:04 | RepitBot.HealthMonitor | ERROR    | health_monitor.py:83 | run_check | Health check bot_connection timeout after 10s
2025-08-23 00:08:04 | RepitBot.HealthMonitor | CRITICAL | health_monitor.py:139 | _handle_critical_failure | üö® CRITICAL: Health check bot_connection failed 1 times
2025-08-23 00:08:06 | RepitBot.HealthMonitor | ERROR    | health_monitor.py:174 | _recover_bot_connection | ‚ùå Failed to recover bot connection: httpx.ConnectError: [Errno 11001] getaddrinfo failed
2025-08-23 00:14:13 | RepitBot.HealthMonitor | ERROR    | health_monitor.py:83 | run_check | Health check bot_connection timeout after 10s
2025-08-23 00:14:13 | RepitBot.HealthMonitor | CRITICAL | health_monitor.py:139 | _handle_critical_failure | üö® CRITICAL: Health check bot_connection failed 1 times
2025-08-23 00:19:52 | RepitBot.HealthMonitor | CRITICAL | health_monitor.py:139 | _handle_critical_failure | üö® CRITICAL: Health check disk_space failed 3 times
2025-08-23 00:24:52 | RepitBot.HealthMonitor | CRITICAL | health_monitor.py:139 | _handle_critical_failure | üö® CRITICAL: Health check disk_space failed 4 times
2025-08-23 00:29:09 | RepitBot | ERROR    | logger.py:228 | log_telegram_error | Telegram error: {'error_type': 'Global Error Handler', 'user_id': None, 'message': None, 'error': 'httpx.RemoteProtocolError: Server disconnected without sending a response.'}
2025-08-23 00:29:28 | RepitBot | ERROR    | logger.py:228 | log_telegram_error | Telegram error: {'error_type': 'Global Error Handler', 'user_id': None, 'message': None, 'error': 'httpx.ReadError: '}
2025-08-23 00:29:54 | RepitBot.HealthMonitor | CRITICAL | health_monitor.py:139 | _handle_critical_failure | üö® CRITICAL: Health check disk_space failed 5 times
2025-08-23 00:32:35 | RepitBot.HealthMonitor | ERROR    | health_monitor.py:83 | run_check | Health check bot_connection timeout after 10s
2025-08-23 00:32:35 | RepitBot.HealthMonitor | CRITICAL | health_monitor.py:139 | _handle_critical_failure | üö® CRITICAL: Health check bot_connection failed 1 times
2025-08-23 00:32:37 | RepitBot.HealthMonitor | ERROR    | health_monitor.py:174 | _recover_bot_connection | ‚ùå Failed to recover bot connection: httpx.ConnectError: [Errno 11001] getaddrinfo failed
2025-08-23 00:34:57 | RepitBot.HealthMonitor | CRITICAL | health_monitor.py:139 | _handle_critical_failure | üö® CRITICAL: Health check disk_space failed 6 times
2025-08-23 00:40:03 | RepitBot.HealthMonitor | CRITICAL | health_monitor.py:139 | _handle_critical_failure | üö® CRITICAL: Health check disk_space failed 7 times
2025-08-23 00:45:06 | RepitBot.HealthMonitor | CRITICAL | health_monitor.py:139 | _handle_critical_failure | üö® CRITICAL: Health check disk_space failed 8 times
2025-08-23 00:50:07 | RepitBot.HealthMonitor | CRITICAL | health_monitor.py:139 | _handle_critical_failure | üö® CRITICAL: Health check disk_space failed 9 times
2025-08-23 00:55:13 | RepitBot.HealthMonitor | CRITICAL | health_monitor.py:139 | _handle_critical_failure | üö® CRITICAL: Health check disk_space failed 10 times
2025-08-23 01:00:14 | RepitBot.HealthMonitor | CRITICAL | health_monitor.py:139 | _handle_critical_failure | üö® CRITICAL: Health check disk_space failed 11 times
2025-08-23 01:05:20 | RepitBot.HealthMonitor | CRITICAL | health_monitor.py:139 | _handle_critical_failure | üö® CRITICAL: Health check disk_space failed 12 times
2025-08-23 01:09:01 | RepitBot.HealthMonitor | ERROR    | health_monitor.py:83 | run_check | Health check bot_connection timeout after 10s
2025-08-23 01:09:01 | RepitBot.HealthMonitor | CRITICAL | health_monitor.py:139 | _handle_critical_failure | üö® CRITICAL: Health check bot_connection failed 1 times
2025-08-23 01:09:12 | RepitBot.HealthMonitor | ERROR    | health_monitor.py:174 | _recover_bot_connection | ‚ùå Failed to recover bot connection: httpx.ConnectError: [Errno 11001] getaddrinfo failed
2025-08-23 01:10:22 | RepitBot.HealthMonitor | CRITICAL | health_monitor.py:139 | _handle_critical_failure | üö® CRITICAL: Health check disk_space failed 13 times
2025-08-23 01:13:02 | RepitBot.HealthMonitor | ERROR    | health_monitor.py:83 | run_check | Health check bot_connection timeout after 10s
2025-08-23 01:13:02 | RepitBot.HealthMonitor | CRITICAL | health_monitor.py:139 | _handle_critical_failure | üö® CRITICAL: Health check bot_connection failed 1 times
2025-08-23 01:13:04 | RepitBot.HealthMonitor | ERROR    | health_monitor.py:174 | _recover_bot_connection | ‚ùå Failed to recover bot connection: httpx.ConnectError: [Errno 11001] getaddrinfo failed
2025-08-23 01:15:24 | RepitBot.HealthMonitor | CRITICAL | health_monitor.py:139 | _handle_critical_failure | üö® CRITICAL: Health check disk_space failed 14 times
2025-08-23 01:20:26 | RepitBot.HealthMonitor | CRITICAL | health_monitor.py:139 | _handle_critical_failure | üö® CRITICAL: Health check disk_space failed 15 times
2025-08-23 01:25:28 | RepitBot.HealthMonitor | CRITICAL | health_monitor.py:139 | _handle_critical_failure | üö® CRITICAL: Health check disk_space failed 16 times
2025-08-23 01:30:29 | RepitBot.HealthMonitor | CRITICAL | health_monitor.py:139 | _handle_critical_failure | üö® CRITICAL: Health check disk_space failed 17 times
2025-08-23 01:35:30 | RepitBot.HealthMonitor | CRITICAL | health_monitor.py:139 | _handle_critical_failure | üö® CRITICAL: Health check disk_space failed 18 times
2025-08-23 01:40:30 | RepitBot.HealthMonitor | CRITICAL | health_monitor.py:139 | _handle_critical_failure | üö® CRITICAL: Health check disk_space failed 19 times
2025-08-23 01:45:38 | RepitBot.HealthMonitor | CRITICAL | health_monitor.py:139 | _handle_critical_failure | üö® CRITICAL: Health check disk_space failed 20 times
2025-08-23 01:50:39 | RepitBot.HealthMonitor | CRITICAL | health_monitor.py:139 | _handle_critical_failure | üö® CRITICAL: Health check disk_space failed 21 times
2025-08-23 01:55:43 | RepitBot.HealthMonitor | CRITICAL | health_monitor.py:139 | _handle_critical_failure | üö® CRITICAL: Health check disk_space failed 22 times
2025-08-23 02:00:45 | RepitBot.HealthMonitor | CRITICAL | health_monitor.py:139 | _handle_critical_failure | üö® CRITICAL: Health check disk_space failed 23 times
2025-08-23 02:05:48 | RepitBot.HealthMonitor | CRITICAL | health_monitor.py:139 | _handle_critical_failure | üö® CRITICAL: Health check disk_space failed 24 times
2025-08-23 02:10:49 | RepitBot.HealthMonitor | CRITICAL | health_monitor.py:139 | _handle_critical_failure | üö® CRITICAL: Health check disk_space failed 25 times
2025-08-23 02:15:51 | RepitBot.HealthMonitor | CRITICAL | health_monitor.py:139 | _handle_critical_failure | üö® CRITICAL: Health check disk_space failed 26 times
2025-08-23 02:21:59 | RepitBot.HealthMonitor | CRITICAL | health_monitor.py:139 | _handle_critical_failure | üö® CRITICAL: Health check disk_space failed 27 times
2025-08-23 02:21:59 | RepitBot | ERROR    | logger.py:228 | log_telegram_error | Telegram error: {'error_type': 'Global Error Handler', 'user_id': None, 'message': None, 'error': 'httpx.ConnectError: [Errno 11001] getaddrinfo failed'}
2025-08-23 02:22:14 | RepitBot | ERROR    | logger.py:228 | log_telegram_error | Telegram error: {'error_type': 'Global Error Handler', 'user_id': None, 'message': None, 'error': 'httpx.ConnectError: [Errno 11001] getaddrinfo failed'}
